{
  "version": 8,
  "blockIdVersion": 11,
  "anchorX": 0,
  "anchorY": 0,
  "anchorZ": 0,
  "blocks": [
    {
      "x": -9,
      "y": 1,
      "z": -9,
      "name": "Rock_Slate_Cobble"
    },
    {
      "x": -9,
      "y": 2,
      "z": -9,
      "name": "Rock_Slate_Cobble"
    },
    {
      "x": -9,
      "y": 3,
      "z": -9,
      "name": "Rock_Slate_Cobble"
    },
    {
      "x": -9,
      "y": 4,
      "z": -9,
      "name": "Rock_Slate_Cobble"
    },
    {
      "x": -9,
      "y": 5,
      "z": -9,
      "name": "Rock_Slate_Cobble"
    },
    {
      "x": -9,
      "y": 6,
      "z": -9,
      "name": "Rock_Slate_Cobble"
    },
    {
      "x": -9,
      "y": 7,
      "z": -9,
      "name": "Rock_Slate_Cobble"
    },
    {
      "x": -9,
      "y": 8,
      "z": -9,
      "name": "Rock_Slate_Cobble"
    },
    {
      "x": -9,
      "y": 1,
      "z": -8,
      "name": "Rock_Slate_Cobble"
    },
    {
      "x": -9,
      "y": 2,
      "z": -8,
      "name": "Rock_Slate_Cobble"
    },
    {
      "x": -9,
      "y": 3,
      "z": -8,
      "name": "Rock_Slate_Cobble"
    },
    {
      "x": -9,
      "y": 4,
      "z": -8,
      "name": "Rock_Slate_Cobble"
    },
    {
      "x": -9,
      "y": 5,
      "z": -8,
      "name": "Rock_Slate_Cobble"
    },
    {
      "x": -9,
      "y": 6,
      "z": -8,
      "name": "Rock_Slate_Cobble"
    },
    {
      "x": -9,
      "y": 7,
      "z": -8,
      "name": "Rock_Slate_Cobble"
    },
    {
      "x": -9,
      "y": 8,
      "z": -8,
      "name": "Rock_Slate_Cobble"
    },
    {
      "x": -9,
      "y": 1,
      "z": -7,
      "name": "Rock_Slate_Cobble"
    },
    {
      "x": -9,
      "y": 2,
      "z": -7,
      "name": "Rock_Slate_Cobble"
    },
    {
      "x": -9,
      "y": 3,
      "z": -7,
      "name": "Rock_Slate_Cobble"
    },
    {
      "x": -9,
      "y": 4,
      "z": -7,
      "name": "Rock_Slate_Cobble"
    },
    {
      "x": -9,
      "y": 5,
      "z": -7,
      "name": "Rock_Slate_Cobble"
    },
    {
      "x": -9,
      "y": 6,
      "z": -7,
      "name": "Rock_Slate_Cobble"
    },
    {
      "x": -9,
      "y": 7,
      "z": -7,
      "name": "Rock_Slate_Cobble"
    },
    {
      "x": -9,
      "y": 8,
      "z": -7,
      "name": "Rock_Slate_Cobble_Half"
    },
    {
      "x": -9,
      "y": 1,
      "z": -6,
      "name": "Rock_Slate_Cobble"
    },
    {
      "x": -9,
      "y": 2,
      "z": -6,
      "name": "Rock_Slate_Cobble"
    },
    {
      "x": -9,
      "y": 3,
      "z": -6,
      "name": "Rock_Slate_Cobble"
    },
    {
      "x": -9,
      "y": 4,
      "z": -6,
      "name": "Rock_Slate_Cobble"
    },
    {
      "x": -9,
      "y": 5,
      "z": -6,
      "name": "Rock_Slate_Cobble"
    },
    {
      "x": -9,
      "y": 6,
      "z": -6,
      "name": "Rock_Slate_Cobble"
    },
    {
      "x": -9,
      "y": 7,
      "z": -6,
      "name": "Rock_Slate_Cobble"
    },
    {
      "x": -9,
      "y": 8,
      "z": -6,
      "name": "Rock_Slate_Cobble_Half"
    },
    {
      "x": -9,
      "y": 1,
      "z": -5,
      "name": "Rock_Slate_Cobble"
    },
    {
      "x": -9,
      "y": 2,
      "z": -5,
      "name": "Rock_Slate_Cobble"
    },
    {
      "x": -9,
      "y": 3,
      "z": -5,
      "name": "Rock_Slate_Cobble"
    },
    {
      "x": -9,
      "y": 4,
      "z": -5,
      "name": "Rock_Slate_Cobble"
    },
    {
      "x": -9,
      "y": 5,
      "z": -5,
      "name": "Rock_Slate_Cobble"
    },
    {
      "x": -9,
      "y": 6,
      "z": -5,
      "name": "Rock_Slate_Cobble"
    },
    {
      "x": -9,
      "y": 7,
      "z": -5,
      "name": "Rock_Slate_Cobble"
    },
    {
      "x": -9,
      "y": 8,
      "z": -5,
      "name": "Rock_Slate_Cobble_Half"
    },
    {
      "x": -9,
      "y": 1,
      "z": -4,
      "name": "Rock_Slate_Cobble"
    },
    {
      "x": -9,
      "y": 2,
      "z": -4,
      "name": "Rock_Slate_Cobble"
    },
    {
      "x": -9,
      "y": 3,
      "z": -4,
      "name": "Rock_Slate_Cobble"
    },
    {
      "x": -9,
      "y": 4,
      "z": -4,
      "name": "Rock_Slate_Cobble"
    },
    {
      "x": -9,
      "y": 5,
      "z": -4,
      "name": "Rock_Slate_Cobble"
    },
    {
      "x": -9,
      "y": 6,
      "z": -4,
      "name": "Rock_Slate_Cobble"
    },
    {
      "x": -9,
      "y": 7,
      "z": -4,
      "name": "Rock_Slate_Cobble"
    },
    {
      "x": -9,
      "y": 8,
      "z": -4,
      "name": "Rock_Slate_Cobble_Half"
    },
    {
      "x": -9,
      "y": 1,
      "z": -3,
      "name": "Rock_Slate_Cobble"
    },
    {
      "x": -9,
      "y": 2,
      "z": -3,
      "name": "Rock_Slate_Cobble"
    },
    {
      "x": -9,
      "y": 3,
      "z": -3,
      "name": "Rock_Slate_Cobble"
    },
    {
      "x": -9,
      "y": 4,
      "z": -3,
      "name": "Rock_Slate_Cobble"
    },
    {
      "x": -9,
      "y": 5,
      "z": -3,
      "name": "Rock_Slate_Cobble"
    },
    {
      "x": -9,
      "y": 6,
      "z": -3,
      "name": "Rock_Slate_Cobble"
    },
    {
      "x": -9,
      "y": 7,
      "z": -3,
      "name": "Rock_Slate_Cobble"
    },
    {
      "x": -9,
      "y": 8,
      "z": -3,
      "name": "Rock_Slate_Cobble_Half"
    },
    {
      "x": -9,
      "y": 1,
      "z": -2,
      "name": "Rock_Slate_Cobble"
    },
    {
      "x": -9,
      "y": 2,
      "z": -2,
      "name": "Rock_Slate_Cobble_Beam",
      "rotation": 1
    },
    {
      "x": -9,
      "y": 3,
      "z": -2,
      "name": "Rock_Slate_Cobble_Beam",
      "rotation": 1
    },
    {
      "x": -9,
      "y": 4,
      "z": -2,
      "name": "Rock_Slate_Cobble_Beam",
      "rotation": 1
    },
    {
      "x": -9,
      "y": 5,
      "z": -2,
      "name": "Rock_Slate_Cobble_Beam",
      "rotation": 1
    },
    {
      "x": -9,
      "y": 6,
      "z": -2,
      "name": "Rock_Slate_Cobble_Beam",
      "rotation": 1
    },
    {
      "x": -9,
      "y": 7,
      "z": -2,
      "name": "Rock_Slate_Cobble",
      "rotation": 1
    },
    {
      "x": -9,
      "y": 8,
      "z": -2,
      "name": "Rock_Slate_Cobble_Half"
    },
    {
      "x": -9,
      "y": 1,
      "z": -1,
      "name": "Rock_Slate_Cobble"
    },
    {
      "x": -9,
      "y": 7,
      "z": -1,
      "name": "Rock_Slate_Stalactite_Small",
      "rotation": 9
    },
    {
      "x": -9,
      "y": 8,
      "z": -1,
      "name": "Rock_Slate_Cobble_Half"
    },
    {
      "x": -9,
      "y": 1,
      "z": 0,
      "name": "Rock_Bedrock",
      "rotation": 1
    },
    {
      "x": -9,
      "y": 7,
      "z": 0,
      "name": "Rock_Slate_Stalactite_Small",
      "rotation": 9
    },
    {
      "x": -9,
      "y": 8,
      "z": 0,
      "name": "Rock_Slate_Cobble",
      "rotation": 1
    },
    {
      "x": -9,
      "y": 1,
      "z": 1,
      "name": "Rock_Slate_Cobble",
      "rotation": 1
    },
    {
      "x": -9,
      "y": 7,
      "z": 1,
      "name": "Rock_Slate_Stalactite_Small",
      "rotation": 9
    },
    {
      "x": -9,
      "y": 8,
      "z": 1,
      "name": "Rock_Slate_Cobble_Half",
      "rotation": 1
    },
    {
      "x": -9,
      "y": 1,
      "z": 2,
      "name": "Rock_Slate_Cobble",
      "rotation": 1
    },
    {
      "x": -9,
      "y": 2,
      "z": 2,
      "name": "Rock_Slate_Cobble_Beam",
      "rotation": 1
    },
    {
      "x": -9,
      "y": 3,
      "z": 2,
      "name": "Rock_Slate_Cobble_Beam",
      "rotation": 1
    },
    {
      "x": -9,
      "y": 4,
      "z": 2,
      "name": "Rock_Slate_Cobble_Beam",
      "rotation": 1
    },
    {
      "x": -9,
      "y": 5,
      "z": 2,
      "name": "Rock_Slate_Cobble_Beam",
      "rotation": 1
    },
    {
      "x": -9,
      "y": 6,
      "z": 2,
      "name": "Rock_Slate_Cobble_Beam",
      "rotation": 1
    },
    {
      "x": -9,
      "y": 7,
      "z": 2,
      "name": "Rock_Slate_Cobble",
      "rotation": 1
    },
    {
      "x": -9,
      "y": 8,
      "z": 2,
      "name": "Rock_Slate_Cobble_Half",
      "rotation": 1
    },
    {
      "x": -9,
      "y": 1,
      "z": 3,
      "name": "Rock_Slate_Cobble"
    },
    {
      "x": -9,
      "y": 2,
      "z": 3,
      "name": "Rock_Slate_Cobble"
    },
    {
      "x": -9,
      "y": 3,
      "z": 3,
      "name": "Rock_Slate_Cobble",
      "rotation": 1
    },
    {
      "x": -9,
      "y": 4,
      "z": 3,
      "name": "Rock_Slate_Cobble",
      "rotation": 1
    },
    {
      "x": -9,
      "y": 5,
      "z": 3,
      "name": "Rock_Slate_Cobble",
      "rotation": 1
    },
    {
      "x": -9,
      "y": 6,
      "z": 3,
      "name": "Rock_Slate_Cobble",
      "rotation": 1
    },
    {
      "x": -9,
      "y": 7,
      "z": 3,
      "name": "Rock_Slate_Cobble",
      "rotation": 1
    },
    {
      "x": -9,
      "y": 8,
      "z": 3,
      "name": "Rock_Slate_Cobble_Half",
      "rotation": 1
    },
    {
      "x": -9,
      "y": 1,
      "z": 4,
      "name": "Rock_Slate_Cobble"
    },
    {
      "x": -9,
      "y": 2,
      "z": 4,
      "name": "Rock_Slate_Cobble"
    },
    {
      "x": -9,
      "y": 3,
      "z": 4,
      "name": "Rock_Slate_Cobble"
    },
    {
      "x": -9,
      "y": 4,
      "z": 4,
      "name": "Rock_Slate_Cobble",
      "rotation": 1
    },
    {
      "x": -9,
      "y": 5,
      "z": 4,
      "name": "Rock_Slate_Cobble",
      "rotation": 1
    },
    {
      "x": -9,
      "y": 6,
      "z": 4,
      "name": "Rock_Slate_Cobble",
      "rotation": 1
    },
    {
      "x": -9,
      "y": 7,
      "z": 4,
      "name": "Rock_Slate_Cobble",
      "rotation": 1
    },
    {
      "x": -9,
      "y": 8,
      "z": 4,
      "name": "Rock_Slate_Cobble_Half",
      "rotation": 1
    },
    {
      "x": -9,
      "y": 1,
      "z": 5,
      "name": "Rock_Slate_Cobble"
    },
    {
      "x": -9,
      "y": 2,
      "z": 5,
      "name": "Rock_Slate_Cobble"
    },
    {
      "x": -9,
      "y": 3,
      "z": 5,
      "name": "Rock_Slate_Cobble"
    },
    {
      "x": -9,
      "y": 4,
      "z": 5,
      "name": "Rock_Slate_Cobble",
      "rotation": 1
    },
    {
      "x": -9,
      "y": 5,
      "z": 5,
      "name": "Rock_Slate_Cobble",
      "rotation": 1
    },
    {
      "x": -9,
      "y": 6,
      "z": 5,
      "name": "Rock_Slate_Cobble",
      "rotation": 1
    },
    {
      "x": -9,
      "y": 7,
      "z": 5,
      "name": "Rock_Slate_Cobble",
      "rotation": 1
    },
    {
      "x": -9,
      "y": 8,
      "z": 5,
      "name": "Rock_Slate_Cobble_Half",
      "rotation": 1
    },
    {
      "x": -9,
      "y": 1,
      "z": 6,
      "name": "Rock_Slate_Cobble"
    },
    {
      "x": -9,
      "y": 2,
      "z": 6,
      "name": "Rock_Slate_Cobble"
    },
    {
      "x": -9,
      "y": 3,
      "z": 6,
      "name": "Rock_Slate_Cobble"
    },
    {
      "x": -9,
      "y": 4,
      "z": 6,
      "name": "Rock_Slate_Cobble",
      "rotation": 1
    },
    {
      "x": -9,
      "y": 5,
      "z": 6,
      "name": "Rock_Slate_Cobble",
      "rotation": 1
    },
    {
      "x": -9,
      "y": 6,
      "z": 6,
      "name": "Rock_Slate_Cobble",
      "rotation": 1
    },
    {
      "x": -9,
      "y": 7,
      "z": 6,
      "name": "Rock_Slate_Cobble",
      "rotation": 1
    },
    {
      "x": -9,
      "y": 8,
      "z": 6,
      "name": "Rock_Slate_Cobble_Half",
      "rotation": 1
    },
    {
      "x": -9,
      "y": 1,
      "z": 7,
      "name": "Rock_Slate_Cobble"
    },
    {
      "x": -9,
      "y": 2,
      "z": 7,
      "name": "Rock_Slate_Cobble"
    },
    {
      "x": -9,
      "y": 3,
      "z": 7,
      "name": "Rock_Slate_Cobble",
      "rotation": 1
    },
    {
      "x": -9,
      "y": 4,
      "z": 7,
      "name": "Rock_Slate_Cobble",
      "rotation": 1
    },
    {
      "x": -9,
      "y": 5,
      "z": 7,
      "name": "Rock_Slate_Cobble",
      "rotation": 1
    },
    {
      "x": -9,
      "y": 6,
      "z": 7,
      "name": "Rock_Slate_Cobble",
      "rotation": 1
    },
    {
      "x": -9,
      "y": 7,
      "z": 7,
      "name": "Rock_Slate_Cobble",
      "rotation": 1
    },
    {
      "x": -9,
      "y": 1,
      "z": 8,
      "name": "Rock_Slate_Cobble",
      "rotation": 1
    },
    {
      "x": -9,
      "y": 2,
      "z": 8,
      "name": "Rock_Slate_Cobble",
      "rotation": 1
    },
    {
      "x": -9,
      "y": 3,
      "z": 8,
      "name": "Rock_Slate_Cobble",
      "rotation": 1
    },
    {
      "x": -9,
      "y": 4,
      "z": 8,
      "name": "Rock_Slate_Cobble",
      "rotation": 1
    },
    {
      "x": -9,
      "y": 5,
      "z": 8,
      "name": "Rock_Slate_Cobble",
      "rotation": 1
    },
    {
      "x": -9,
      "y": 6,
      "z": 8,
      "name": "Rock_Slate_Cobble",
      "rotation": 1
    },
    {
      "x": -9,
      "y": 7,
      "z": 8,
      "name": "Rock_Slate_Cobble",
      "rotation": 1
    },
    {
      "x": -9,
      "y": 8,
      "z": 8,
      "name": "Rock_Slate_Cobble",
      "rotation": 1
    },
    {
      "x": -9,
      "y": 0,
      "z": 9,
      "name": "Rock_Slate_Cobble"
    },
    {
      "x": -9,
      "y": 1,
      "z": 9,
      "name": "Rock_Slate_Cobble",
      "rotation": 1
    },
    {
      "x": -9,
      "y": 2,
      "z": 9,
      "name": "Rock_Slate_Cobble",
      "rotation": 1
    },
    {
      "x": -9,
      "y": 3,
      "z": 9,
      "name": "Rock_Slate_Cobble",
      "rotation": 1
    },
    {
      "x": -9,
      "y": 4,
      "z": 9,
      "name": "Rock_Slate_Cobble",
      "rotation": 1
    },
    {
      "x": -9,
      "y": 5,
      "z": 9,
      "name": "Rock_Slate_Cobble",
      "rotation": 1
    },
    {
      "x": -9,
      "y": 6,
      "z": 9,
      "name": "Rock_Slate_Cobble",
      "rotation": 1
    },
    {
      "x": -9,
      "y": 7,
      "z": 9,
      "name": "Rock_Slate_Cobble",
      "rotation": 1
    },
    {
      "x": -9,
      "y": 8,
      "z": 9,
      "name": "Rock_Slate_Cobble"
    },
    {
      "x": -8,
      "y": 1,
      "z": -9,
      "name": "Rock_Slate_Cobble"
    },
    {
      "x": -8,
      "y": 2,
      "z": -9,
      "name": "Rock_Slate_Cobble"
    },
    {
      "x": -8,
      "y": 3,
      "z": -9,
      "name": "Rock_Slate_Cobble"
    },
    {
      "x": -8,
      "y": 4,
      "z": -9,
      "name": "Rock_Slate_Cobble"
    },
    {
      "x": -8,
      "y": 5,
      "z": -9,
      "name": "Rock_Slate_Cobble"
    },
    {
      "x": -8,
      "y": 6,
      "z": -9,
      "name": "Rock_Slate_Cobble"
    },
    {
      "x": -8,
      "y": 7,
      "z": -9,
      "name": "Rock_Slate_Cobble"
    },
    {
      "x": -8,
      "y": 8,
      "z": -9,
      "name": "Rock_Slate_Cobble"
    },
    {
      "x": -8,
      "y": 0,
      "z": -8,
      "name": "Rock_Slate_Cobble"
    },
    {
      "x": -8,
      "y": 8,
      "z": -8,
      "name": "Rock_Slate_Cobble"
    },
    {
      "x": -8,
      "y": 0,
      "z": -7,
      "name": "Rock_Slate_Cobble"
    },
    {
      "x": -8,
      "y": 8,
      "z": -7,
      "name": "Rock_Slate_Cobble"
    },
    {
      "x": -8,
      "y": 0,
      "z": -6,
      "name": "Rock_Slate_Cobble"
    },
    {
      "x": -8,
      "y": 8,
      "z": -6,
      "name": "Rock_Slate_Cobble_Half"
    },
    {
      "x": -8,
      "y": 0,
      "z": -5,
      "name": "Rock_Slate_Cobble"
    },
    {
      "x": -8,
      "y": 8,
      "z": -5,
      "name": "Rock_Slate_Cobble_Half"
    },
    {
      "x": -8,
      "y": 0,
      "z": -4,
      "name": "Rock_Slate_Cobble"
    },
    {
      "x": -8,
      "y": 8,
      "z": -4,
      "name": "Rock_Slate_Cobble_Half"
    },
    {
      "x": -8,
      "y": 0,
      "z": -3,
      "name": "Rock_Slate_Cobble"
    },
    {
      "x": -8,
      "y": 8,
      "z": -3,
      "name": "Rock_Slate_Cobble_Half"
    },
    {
      "x": -8,
      "y": 0,
      "z": -2,
      "name": "Rock_Slate_Cobble"
    },
    {
      "x": -8,
      "y": 8,
      "z": -2,
      "name": "Rock_Slate_Cobble_Half"
    },
    {
      "x": -8,
      "y": 0,
      "z": -1,
      "name": "Rock_Slate_Cobble"
    },
    {
      "x": -8,
      "y": 8,
      "z": -1,
      "name": "Rock_Slate_Cobble_Half"
    },
    {
      "x": -8,
      "y": 0,
      "z": 0,
      "name": "Rock_Slate_Cobble"
    },
    {
      "x": -8,
      "y": 8,
      "z": 0,
      "name": "Rock_Slate_Cobble",
      "rotation": 1
    },
    {
      "x": -8,
      "y": 0,
      "z": 1,
      "name": "Rock_Slate_Cobble",
      "rotation": 1
    },
    {
      "x": -8,
      "y": 8,
      "z": 1,
      "name": "Rock_Slate_Cobble_Half",
      "rotation": 1
    },
    {
      "x": -8,
      "y": 0,
      "z": 2,
      "name": "Rock_Slate_Cobble",
      "rotation": 1
    },
    {
      "x": -8,
      "y": 8,
      "z": 2,
      "name": "Rock_Slate_Cobble_Half",
      "rotation": 1
    },
    {
      "x": -8,
      "y": 0,
      "z": 3,
      "name": "Rock_Slate_Cobble"
    },
    {
      "x": -8,
      "y": 8,
      "z": 3,
      "name": "Rock_Slate_Cobble_Half",
      "rotation": 1
    },
    {
      "x": -8,
      "y": 0,
      "z": 4,
      "name": "Rock_Slate_Cobble"
    },
    {
      "x": -8,
      "y": 8,
      "z": 4,
      "name": "Rock_Slate_Cobble_Half",
      "rotation": 1
    },
    {
      "x": -8,
      "y": 0,
      "z": 5,
      "name": "Rock_Slate_Cobble"
    },
    {
      "x": -8,
      "y": 8,
      "z": 5,
      "name": "Rock_Slate_Cobble_Half",
      "rotation": 1
    },
    {
      "x": -8,
      "y": 0,
      "z": 6,
      "name": "Rock_Slate_Cobble"
    },
    {
      "x": -8,
      "y": 8,
      "z": 6,
      "name": "Rock_Slate_Cobble_Half",
      "rotation": 1
    },
    {
      "x": -8,
      "y": 0,
      "z": 7,
      "name": "Rock_Slate_Cobble"
    },
    {
      "x": -8,
      "y": 8,
      "z": 7,
      "name": "Rock_Slate_Cobble",
      "rotation": 1
    },
    {
      "x": -8,
      "y": 0,
      "z": 8,
      "name": "Rock_Slate_Cobble",
      "rotation": 1
    },
    {
      "x": -8,
      "y": 8,
      "z": 8,
      "name": "Rock_Slate_Cobble"
    },
    {
      "x": -8,
      "y": 1,
      "z": 9,
      "name": "Rock_Slate_Cobble",
      "rotation": 1
    },
    {
      "x": -8,
      "y": 2,
      "z": 9,
      "name": "Rock_Slate_Cobble",
      "rotation": 1
    },
    {
      "x": -8,
      "y": 3,
      "z": 9,
      "name": "Rock_Slate_Cobble",
      "rotation": 1
    },
    {
      "x": -8,
      "y": 4,
      "z": 9,
      "name": "Rock_Slate_Cobble",
      "rotation": 1
    },
    {
      "x": -8,
      "y": 5,
      "z": 9,
      "name": "Rock_Slate_Cobble",
      "rotation": 1
    },
    {
      "x": -8,
      "y": 6,
      "z": 9,
      "name": "Rock_Slate_Cobble",
      "rotation": 1
    },
    {
      "x": -8,
      "y": 7,
      "z": 9,
      "name": "Rock_Slate_Cobble",
      "rotation": 1
    },
    {
      "x": -8,
      "y": 8,
      "z": 9,
      "name": "Rock_Slate_Cobble",
      "rotation": 1
    },
    {
      "x": -7,
      "y": 1,
      "z": -9,
      "name": "Rock_Slate_Cobble"
    },
    {
      "x": -7,
      "y": 2,
      "z": -9,
      "name": "Rock_Slate_Cobble"
    },
    {
      "x": -7,
      "y": 3,
      "z": -9,
      "name": "Rock_Slate_Cobble"
    },
    {
      "x": -7,
      "y": 4,
      "z": -9,
      "name": "Rock_Slate_Cobble"
    },
    {
      "x": -7,
      "y": 5,
      "z": -9,
      "name": "Rock_Slate_Cobble"
    },
    {
      "x": -7,
      "y": 6,
      "z": -9,
      "name": "Rock_Slate_Cobble"
    },
    {
      "x": -7,
      "y": 7,
      "z": -9,
      "name": "Rock_Slate_Cobble"
    },
    {
      "x": -7,
      "y": 0,
      "z": -8,
      "name": "Rock_Slate_Cobble"
    },
    {
      "x": -7,
      "y": 8,
      "z": -8,
      "name": "Rock_Slate_Cobble"
    },
    {
      "x": -7,
      "y": 0,
      "z": -7,
      "name": "Rock_Slate_Cobble"
    },
    {
      "x": -7,
      "y": 8,
      "z": -7,
      "name": "Rock_Slate_Cobble_Half"
    },
    {
      "x": -7,
      "y": 0,
      "z": -6,
      "name": "Rock_Slate_Cobble"
    },
    {
      "x": -7,
      "y": 8,
      "z": -6,
      "name": "Rock_Slate_Cobble_Half"
    },
    {
      "x": -7,
      "y": 0,
      "z": -5,
      "name": "Rock_Slate_Cobble"
    },
    {
      "x": -7,
      "y": 8,
      "z": -5,
      "name": "Rock_Slate_Cobble_Half"
    },
    {
      "x": -7,
      "y": 0,
      "z": -4,
      "name": "Rock_Slate_Cobble"
    },
    {
      "x": -7,
      "y": 8,
      "z": -4,
      "name": "Rock_Slate_Cobble_Half"
    },
    {
      "x": -7,
      "y": 0,
      "z": -3,
      "name": "Rock_Slate_Cobble"
    },
    {
      "x": -7,
      "y": 8,
      "z": -3,
      "name": "Rock_Slate_Cobble_Half"
    },
    {
      "x": -7,
      "y": 0,
      "z": -2,
      "name": "Rock_Slate_Cobble"
    },
    {
      "x": -7,
      "y": 8,
      "z": -2,
      "name": "Rock_Slate_Cobble_Half"
    },
    {
      "x": -7,
      "y": 0,
      "z": -1,
      "name": "Rock_Slate_Cobble"
    },
    {
      "x": -7,
      "y": 8,
      "z": -1,
      "name": "Rock_Slate_Cobble_Half"
    },
    {
      "x": -7,
      "y": 0,
      "z": 0,
      "name": "Rock_Slate_Cobble"
    },
    {
      "x": -7,
      "y": 8,
      "z": 0,
      "name": "Rock_Slate_Cobble",
      "rotation": 1
    },
    {
      "x": -7,
      "y": 0,
      "z": 1,
      "name": "Rock_Slate_Cobble",
      "rotation": 1
    },
    {
      "x": -7,
      "y": 8,
      "z": 1,
      "name": "Rock_Slate_Cobble_Half",
      "rotation": 1
    },
    {
      "x": -7,
      "y": 0,
      "z": 2,
      "name": "Rock_Slate_Cobble"
    },
    {
      "x": -7,
      "y": 8,
      "z": 2,
      "name": "Rock_Slate_Cobble_Half",
      "rotation": 1
    },
    {
      "x": -7,
      "y": 0,
      "z": 3,
      "name": "Rock_Slate_Cobble"
    },
    {
      "x": -7,
      "y": 8,
      "z": 3,
      "name": "Rock_Slate_Cobble_Half",
      "rotation": 1
    },
    {
      "x": -7,
      "y": 0,
      "z": 4,
      "name": "Rock_Slate_Cobble"
    },
    {
      "x": -7,
      "y": 8,
      "z": 4,
      "name": "Rock_Slate_Cobble_Half",
      "rotation": 1
    },
    {
      "x": -7,
      "y": 0,
      "z": 5,
      "name": "Rock_Slate_Cobble"
    },
    {
      "x": -7,
      "y": 8,
      "z": 5,
      "name": "Rock_Slate_Cobble_Half",
      "rotation": 1
    },
    {
      "x": -7,
      "y": 0,
      "z": 6,
      "name": "Rock_Slate_Cobble"
    },
    {
      "x": -7,
      "y": 8,
      "z": 6,
      "name": "Rock_Slate_Cobble_Half",
      "rotation": 1
    },
    {
      "x": -7,
      "y": 0,
      "z": 7,
      "name": "Rock_Slate_Cobble"
    },
    {
      "x": -7,
      "y": 8,
      "z": 7,
      "name": "Rock_Slate_Cobble_Half",
      "rotation": 1
    },
    {
      "x": -7,
      "y": 0,
      "z": 8,
      "name": "Rock_Slate_Cobble"
    },
    {
      "x": -7,
      "y": 8,
      "z": 8,
      "name": "Rock_Slate_Cobble",
      "rotation": 1
    },
    {
      "x": -7,
      "y": 1,
      "z": 9,
      "name": "Rock_Slate_Cobble",
      "rotation": 1
    },
    {
      "x": -7,
      "y": 2,
      "z": 9,
      "name": "Rock_Slate_Cobble",
      "rotation": 1
    },
    {
      "x": -7,
      "y": 3,
      "z": 9,
      "name": "Rock_Slate_Cobble",
      "rotation": 1
    },
    {
      "x": -7,
      "y": 4,
      "z": 9,
      "name": "Rock_Slate_Cobble",
      "rotation": 1
    },
    {
      "x": -7,
      "y": 5,
      "z": 9,
      "name": "Rock_Slate_Cobble",
      "rotation": 1
    },
    {
      "x": -7,
      "y": 6,
      "z": 9,
      "name": "Rock_Slate_Cobble",
      "rotation": 1
    },
    {
      "x": -7,
      "y": 7,
      "z": 9,
      "name": "Rock_Slate_Cobble",
      "rotation": 1
    },
    {
      "x": -7,
      "y": 8,
      "z": 9,
      "name": "Rock_Slate_Cobble_Half",
      "rotation": 1
    },
    {
      "x": -6,
      "y": 1,
      "z": -9,
      "name": "Rock_Slate_Cobble"
    },
    {
      "x": -6,
      "y": 2,
      "z": -9,
      "name": "Rock_Slate_Cobble"
    },
    {
      "x": -6,
      "y": 3,
      "z": -9,
      "name": "Rock_Slate_Cobble"
    },
    {
      "x": -6,
      "y": 4,
      "z": -9,
      "name": "Rock_Slate_Cobble"
    },
    {
      "x": -6,
      "y": 5,
      "z": -9,
      "name": "Rock_Slate_Cobble"
    },
    {
      "x": -6,
      "y": 6,
      "z": -9,
      "name": "Rock_Slate_Cobble"
    },
    {
      "x": -6,
      "y": 7,
      "z": -9,
      "name": "Rock_Slate_Cobble"
    },
    {
      "x": -6,
      "y": 8,
      "z": -9,
      "name": "Rock_Slate_Cobble_Half"
    },
    {
      "x": -6,
      "y": 0,
      "z": -8,
      "name": "Rock_Slate_Cobble"
    },
    {
      "x": -6,
      "y": 8,
      "z": -8,
      "name": "Rock_Slate_Cobble_Half"
    },
    {
      "x": -6,
      "y": 0,
      "z": -7,
      "name": "Rock_Slate_Cobble"
    },
    {
      "x": -6,
      "y": 8,
      "z": -7,
      "name": "Rock_Slate_Cobble_Half"
    },
    {
      "x": -6,
      "y": 0,
      "z": -6,
      "name": "Rock_Slate_Cobble"
    },
    {
      "x": -6,
      "y": 8,
      "z": -6,
      "name": "Rock_Slate_Cobble_Half"
    },
    {
      "x": -6,
      "y": 0,
      "z": -5,
      "name": "Rock_Slate_Cobble"
    },
    {
      "x": -6,
      "y": 8,
      "z": -5,
      "name": "Rock_Slate_Cobble_Half"
    },
    {
      "x": -6,
      "y": 0,
      "z": -4,
      "name": "Rock_Slate_Cobble"
    },
    {
      "x": -6,
      "y": 8,
      "z": -4,
      "name": "Rock_Slate_Cobble_Half"
    },
    {
      "x": -6,
      "y": 0,
      "z": -3,
      "name": "Rock_Slate_Cobble"
    },
    {
      "x": -6,
      "y": 1,
      "z": -3,
      "name": "Rock_Slate_Cobble"
    },
    {
      "x": -6,
      "y": 2,
      "z": -3,
      "name": "Rock_Slate_Cobble_Beam"
    },
    {
      "x": -6,
      "y": 3,
      "z": -3,
      "name": "Rock_Slate_Cobble_Beam"
    },
    {
      "x": -6,
      "y": 4,
      "z": -3,
      "name": "Rock_Slate_Cobble_Beam"
    },
    {
      "x": -6,
      "y": 5,
      "z": -3,
      "name": "Rock_Slate_Cobble_Beam"
    },
    {
      "x": -6,
      "y": 6,
      "z": -3,
      "name": "Rock_Slate_Cobble_Beam"
    },
    {
      "x": -6,
      "y": 7,
      "z": -3,
      "name": "Rock_Slate_Cobble_Beam"
    },
    {
      "x": -6,
      "y": 8,
      "z": -3,
      "name": "Rock_Slate_Cobble_Half"
    },
    {
      "x": -6,
      "y": 0,
      "z": -2,
      "name": "Rock_Slate_Cobble"
    },
    {
      "x": -6,
      "y": 8,
      "z": -2,
      "name": "Rock_Slate_Cobble_Half"
    },
    {
      "x": -6,
      "y": 0,
      "z": -1,
      "name": "Rock_Slate_Cobble"
    },
    {
      "x": -6,
      "y": 8,
      "z": -1,
      "name": "Rock_Slate_Cobble_Half"
    },
    {
      "x": -6,
      "y": 0,
      "z": 0,
      "name": "Rock_Slate_Cobble"
    },
    {
      "x": -6,
      "y": 8,
      "z": 0,
      "name": "Rock_Slate_Cobble",
      "rotation": 1
    },
    {
      "x": -6,
      "y": 0,
      "z": 1,
      "name": "Rock_Slate_Cobble",
      "rotation": 1
    },
    {
      "x": -6,
      "y": 8,
      "z": 1,
      "name": "Rock_Slate_Cobble_Half",
      "rotation": 1
    },
    {
      "x": -6,
      "y": 0,
      "z": 2,
      "name": "Rock_Slate_Cobble"
    },
    {
      "x": -6,
      "y": 8,
      "z": 2,
      "name": "Rock_Slate_Cobble_Half",
      "rotation": 1
    },
    {
      "x": -6,
      "y": 0,
      "z": 3,
      "name": "Rock_Slate_Cobble"
    },
    {
      "x": -6,
      "y": 1,
      "z": 3,
      "name": "Rock_Slate_Cobble"
    },
    {
      "x": -6,
      "y": 2,
      "z": 3,
      "name": "Rock_Slate_Cobble_Beam"
    },
    {
      "x": -6,
      "y": 3,
      "z": 3,
      "name": "Rock_Slate_Cobble_Beam"
    },
    {
      "x": -6,
      "y": 4,
      "z": 3,
      "name": "Rock_Slate_Cobble_Beam"
    },
    {
      "x": -6,
      "y": 5,
      "z": 3,
      "name": "Rock_Slate_Cobble_Beam",
      "rotation": 1
    },
    {
      "x": -6,
      "y": 6,
      "z": 3,
      "name": "Rock_Slate_Cobble_Beam",
      "rotation": 1
    },
    {
      "x": -6,
      "y": 7,
      "z": 3,
      "name": "Rock_Slate_Cobble_Beam",
      "rotation": 1
    },
    {
      "x": -6,
      "y": 8,
      "z": 3,
      "name": "Rock_Slate_Cobble_Half",
      "rotation": 1
    },
    {
      "x": -6,
      "y": 0,
      "z": 4,
      "name": "Rock_Slate_Cobble"
    },
    {
      "x": -6,
      "y": 8,
      "z": 4,
      "name": "Rock_Slate_Cobble_Half",
      "rotation": 1
    },
    {
      "x": -6,
      "y": 0,
      "z": 5,
      "name": "Rock_Slate_Cobble"
    },
    {
      "x": -6,
      "y": 8,
      "z": 5,
      "name": "Rock_Slate_Cobble_Half",
      "rotation": 1
    },
    {
      "x": -6,
      "y": 0,
      "z": 6,
      "name": "Rock_Slate_Cobble"
    },
    {
      "x": -6,
      "y": 8,
      "z": 6,
      "name": "Rock_Slate_Cobble_Half",
      "rotation": 1
    },
    {
      "x": -6,
      "y": 0,
      "z": 7,
      "name": "Rock_Slate_Cobble"
    },
    {
      "x": -6,
      "y": 8,
      "z": 7,
      "name": "Rock_Slate_Cobble_Half",
      "rotation": 1
    },
    {
      "x": -6,
      "y": 0,
      "z": 8,
      "name": "Rock_Slate_Cobble"
    },
    {
      "x": -6,
      "y": 8,
      "z": 8,
      "name": "Rock_Slate_Cobble_Half",
      "rotation": 1
    },
    {
      "x": -6,
      "y": 1,
      "z": 9,
      "name": "Rock_Slate_Cobble",
      "rotation": 1
    },
    {
      "x": -6,
      "y": 2,
      "z": 9,
      "name": "Rock_Slate_Cobble",
      "rotation": 1
    },
    {
      "x": -6,
      "y": 3,
      "z": 9,
      "name": "Rock_Slate_Cobble",
      "rotation": 1
    },
    {
      "x": -6,
      "y": 4,
      "z": 9,
      "name": "Rock_Slate_Cobble",
      "rotation": 1
    },
    {
      "x": -6,
      "y": 5,
      "z": 9,
      "name": "Rock_Slate_Cobble",
      "rotation": 1
    },
    {
      "x": -6,
      "y": 6,
      "z": 9,
      "name": "Rock_Slate_Cobble",
      "rotation": 1
    },
    {
      "x": -6,
      "y": 7,
      "z": 9,
      "name": "Rock_Slate_Cobble",
      "rotation": 1
    },
    {
      "x": -6,
      "y": 8,
      "z": 9,
      "name": "Rock_Slate_Cobble_Half",
      "rotation": 1
    },
    {
      "x": -5,
      "y": 1,
      "z": -9,
      "name": "Rock_Slate_Cobble"
    },
    {
      "x": -5,
      "y": 2,
      "z": -9,
      "name": "Rock_Slate_Cobble"
    },
    {
      "x": -5,
      "y": 3,
      "z": -9,
      "name": "Rock_Slate_Cobble"
    },
    {
      "x": -5,
      "y": 4,
      "z": -9,
      "name": "Rock_Slate_Cobble"
    },
    {
      "x": -5,
      "y": 5,
      "z": -9,
      "name": "Rock_Slate_Cobble"
    },
    {
      "x": -5,
      "y": 6,
      "z": -9,
      "name": "Rock_Slate_Cobble"
    },
    {
      "x": -5,
      "y": 7,
      "z": -9,
      "name": "Rock_Slate_Cobble"
    },
    {
      "x": -5,
      "y": 8,
      "z": -9,
      "name": "Rock_Slate_Cobble_Half"
    },
    {
      "x": -5,
      "y": 0,
      "z": -8,
      "name": "Rock_Slate_Cobble"
    },
    {
      "x": -5,
      "y": 8,
      "z": -8,
      "name": "Rock_Slate_Cobble_Half"
    },
    {
      "x": -5,
      "y": 0,
      "z": -7,
      "name": "Rock_Slate_Cobble"
    },
    {
      "x": -5,
      "y": 8,
      "z": -7,
      "name": "Rock_Slate_Cobble_Half"
    },
    {
      "x": -5,
      "y": 0,
      "z": -6,
      "name": "Rock_Slate_Cobble"
    },
    {
      "x": -5,
      "y": 8,
      "z": -6,
      "name": "Rock_Slate_Cobble_Half"
    },
    {
      "x": -5,
      "y": 0,
      "z": -5,
      "name": "Rock_Slate_Cobble"
    },
    {
      "x": -5,
      "y": 8,
      "z": -5,
      "name": "Rock_Slate_Cobble_Half"
    },
    {
      "x": -5,
      "y": 0,
      "z": -4,
      "name": "Rock_Slate_Cobble"
    },
    {
      "x": -5,
      "y": 8,
      "z": -4,
      "name": "Rock_Slate_Cobble_Half"
    },
    {
      "x": -5,
      "y": 0,
      "z": -3,
      "name": "Rock_Slate_Cobble"
    },
    {
      "x": -5,
      "y": 8,
      "z": -3,
      "name": "Rock_Slate_Cobble_Half"
    },
    {
      "x": -5,
      "y": 0,
      "z": -2,
      "name": "Rock_Slate_Cobble"
    },
    {
      "x": -5,
      "y": 8,
      "z": -2,
      "name": "Rock_Slate_Cobble_Half"
    },
    {
      "x": -5,
      "y": 0,
      "z": -1,
      "name": "Rock_Slate_Cobble"
    },
    {
      "x": -5,
      "y": 8,
      "z": -1,
      "name": "Rock_Slate_Cobble_Half"
    },
    {
      "x": -5,
      "y": 0,
      "z": 0,
      "name": "Rock_Slate_Cobble"
    },
    {
      "x": -5,
      "y": 8,
      "z": 0,
      "name": "Rock_Slate_Cobble",
      "rotation": 1
    },
    {
      "x": -5,
      "y": 0,
      "z": 1,
      "name": "Rock_Slate_Cobble"
    },
    {
      "x": -5,
      "y": 8,
      "z": 1,
      "name": "Rock_Slate_Cobble_Half",
      "rotation": 1
    },
    {
      "x": -5,
      "y": 0,
      "z": 2,
      "name": "Rock_Slate_Cobble"
    },
    {
      "x": -5,
      "y": 8,
      "z": 2,
      "name": "Rock_Slate_Cobble_Half",
      "rotation": 1
    },
    {
      "x": -5,
      "y": 0,
      "z": 3,
      "name": "Rock_Slate_Cobble"
    },
    {
      "x": -5,
      "y": 8,
      "z": 3,
      "name": "Rock_Slate_Cobble_Half",
      "rotation": 1
    },
    {
      "x": -5,
      "y": 0,
      "z": 4,
      "name": "Rock_Slate_Cobble"
    },
    {
      "x": -5,
      "y": 8,
      "z": 4,
      "name": "Rock_Slate_Cobble_Half",
      "rotation": 1
    },
    {
      "x": -5,
      "y": 0,
      "z": 5,
      "name": "Rock_Slate_Cobble"
    },
    {
      "x": -5,
      "y": 8,
      "z": 5,
      "name": "Rock_Slate_Cobble_Half",
      "rotation": 1
    },
    {
      "x": -5,
      "y": 0,
      "z": 6,
      "name": "Rock_Slate_Cobble"
    },
    {
      "x": -5,
      "y": 8,
      "z": 6,
      "name": "Rock_Slate_Cobble_Half",
      "rotation": 1
    },
    {
      "x": -5,
      "y": 0,
      "z": 7,
      "name": "Rock_Slate_Cobble"
    },
    {
      "x": -5,
      "y": 8,
      "z": 7,
      "name": "Rock_Slate_Cobble_Half",
      "rotation": 1
    },
    {
      "x": -5,
      "y": 0,
      "z": 8,
      "name": "Rock_Slate_Cobble"
    },
    {
      "x": -5,
      "y": 8,
      "z": 8,
      "name": "Rock_Slate_Cobble_Half",
      "rotation": 1
    },
    {
      "x": -5,
      "y": 1,
      "z": 9,
      "name": "Rock_Slate_Cobble",
      "rotation": 1
    },
    {
      "x": -5,
      "y": 2,
      "z": 9,
      "name": "Rock_Slate_Cobble",
      "rotation": 1
    },
    {
      "x": -5,
      "y": 3,
      "z": 9,
      "name": "Rock_Slate_Cobble",
      "rotation": 1
    },
    {
      "x": -5,
      "y": 4,
      "z": 9,
      "name": "Rock_Slate_Cobble",
      "rotation": 1
    },
    {
      "x": -5,
      "y": 5,
      "z": 9,
      "name": "Rock_Slate_Cobble",
      "rotation": 1
    },
    {
      "x": -5,
      "y": 6,
      "z": 9,
      "name": "Rock_Slate_Cobble",
      "rotation": 1
    },
    {
      "x": -5,
      "y": 7,
      "z": 9,
      "name": "Rock_Slate_Cobble",
      "rotation": 1
    },
    {
      "x": -5,
      "y": 8,
      "z": 9,
      "name": "Rock_Slate_Cobble_Half",
      "rotation": 1
    },
    {
      "x": -4,
      "y": 1,
      "z": -9,
      "name": "Rock_Slate_Cobble"
    },
    {
      "x": -4,
      "y": 2,
      "z": -9,
      "name": "Rock_Slate_Cobble"
    },
    {
      "x": -4,
      "y": 3,
      "z": -9,
      "name": "Rock_Slate_Cobble"
    },
    {
      "x": -4,
      "y": 4,
      "z": -9,
      "name": "Rock_Slate_Cobble"
    },
    {
      "x": -4,
      "y": 5,
      "z": -9,
      "name": "Rock_Slate_Cobble"
    },
    {
      "x": -4,
      "y": 6,
      "z": -9,
      "name": "Rock_Slate_Cobble"
    },
    {
      "x": -4,
      "y": 7,
      "z": -9,
      "name": "Rock_Slate_Cobble"
    },
    {
      "x": -4,
      "y": 8,
      "z": -9,
      "name": "Rock_Slate_Cobble_Half"
    },
    {
      "x": -4,
      "y": 0,
      "z": -8,
      "name": "Rock_Slate_Cobble"
    },
    {
      "x": -4,
      "y": 8,
      "z": -8,
      "name": "Rock_Slate_Cobble_Half"
    },
    {
      "x": -4,
      "y": 0,
      "z": -7,
      "name": "Rock_Slate_Cobble"
    },
    {
      "x": -4,
      "y": 8,
      "z": -7,
      "name": "Rock_Slate_Cobble_Half"
    },
    {
      "x": -4,
      "y": 0,
      "z": -6,
      "name": "Rock_Slate_Cobble"
    },
    {
      "x": -4,
      "y": 8,
      "z": -6,
      "name": "Rock_Slate_Cobble_Half"
    },
    {
      "x": -4,
      "y": 0,
      "z": -5,
      "name": "Rock_Slate_Cobble"
    },
    {
      "x": -4,
      "y": 8,
      "z": -5,
      "name": "Rock_Slate_Cobble_Half"
    },
    {
      "x": -4,
      "y": 0,
      "z": -4,
      "name": "Rock_Slate_Cobble"
    },
    {
      "x": -4,
      "y": 8,
      "z": -4,
      "name": "Rock_Slate_Cobble_Half"
    },
    {
      "x": -4,
      "y": 0,
      "z": -3,
      "name": "Rock_Slate_Cobble"
    },
    {
      "x": -4,
      "y": 8,
      "z": -3,
      "name": "Rock_Slate_Cobble_Half"
    },
    {
      "x": -4,
      "y": 0,
      "z": -2,
      "name": "Rock_Slate_Cobble"
    },
    {
      "x": -4,
      "y": 8,
      "z": -2,
      "name": "Rock_Slate_Cobble_Half"
    },
    {
      "x": -4,
      "y": 0,
      "z": -1,
      "name": "Rock_Slate_Cobble"
    },
    {
      "x": -4,
      "y": 8,
      "z": -1,
      "name": "Rock_Slate_Cobble_Half"
    },
    {
      "x": -4,
      "y": 0,
      "z": 0,
      "name": "Rock_Slate_Cobble"
    },
    {
      "x": -4,
      "y": 8,
      "z": 0,
      "name": "Rock_Slate_Cobble",
      "rotation": 1
    },
    {
      "x": -4,
      "y": 0,
      "z": 1,
      "name": "Rock_Slate_Cobble"
    },
    {
      "x": -4,
      "y": 8,
      "z": 1,
      "name": "Rock_Slate_Cobble_Half",
      "rotation": 1
    },
    {
      "x": -4,
      "y": 0,
      "z": 2,
      "name": "Rock_Slate_Cobble"
    },
    {
      "x": -4,
      "y": 8,
      "z": 2,
      "name": "Rock_Slate_Cobble_Half",
      "rotation": 1
    },
    {
      "x": -4,
      "y": 0,
      "z": 3,
      "name": "Rock_Slate_Cobble"
    },
    {
      "x": -4,
      "y": 8,
      "z": 3,
      "name": "Rock_Slate_Cobble_Half",
      "rotation": 1
    },
    {
      "x": -4,
      "y": 0,
      "z": 4,
      "name": "Rock_Slate_Cobble"
    },
    {
      "x": -4,
      "y": 8,
      "z": 4,
      "name": "Rock_Slate_Cobble_Half",
      "rotation": 1
    },
    {
      "x": -4,
      "y": 0,
      "z": 5,
      "name": "Rock_Slate_Cobble"
    },
    {
      "x": -4,
      "y": 8,
      "z": 5,
      "name": "Rock_Slate_Cobble_Half",
      "rotation": 1
    },
    {
      "x": -4,
      "y": 0,
      "z": 6,
      "name": "Rock_Slate_Cobble"
    },
    {
      "x": -4,
      "y": 8,
      "z": 6,
      "name": "Rock_Slate_Cobble_Half",
      "rotation": 1
    },
    {
      "x": -4,
      "y": 0,
      "z": 7,
      "name": "Rock_Slate_Cobble"
    },
    {
      "x": -4,
      "y": 8,
      "z": 7,
      "name": "Rock_Slate_Cobble_Half",
      "rotation": 1
    },
    {
      "x": -4,
      "y": 0,
      "z": 8,
      "name": "Rock_Slate_Cobble",
      "rotation": 1
    },
    {
      "x": -4,
      "y": 8,
      "z": 8,
      "name": "Rock_Slate_Cobble_Half",
      "rotation": 1
    },
    {
      "x": -4,
      "y": 1,
      "z": 9,
      "name": "Rock_Slate_Cobble",
      "rotation": 1
    },
    {
      "x": -4,
      "y": 2,
      "z": 9,
      "name": "Rock_Slate_Cobble",
      "rotation": 1
    },
    {
      "x": -4,
      "y": 3,
      "z": 9,
      "name": "Rock_Slate_Cobble",
      "rotation": 1
    },
    {
      "x": -4,
      "y": 4,
      "z": 9,
      "name": "Rock_Slate_Cobble",
      "rotation": 1
    },
    {
      "x": -4,
      "y": 5,
      "z": 9,
      "name": "Rock_Slate_Cobble",
      "rotation": 1
    },
    {
      "x": -4,
      "y": 6,
      "z": 9,
      "name": "Rock_Slate_Cobble",
      "rotation": 1
    },
    {
      "x": -4,
      "y": 7,
      "z": 9,
      "name": "Rock_Slate_Cobble",
      "rotation": 1
    },
    {
      "x": -4,
      "y": 8,
      "z": 9,
      "name": "Rock_Slate_Cobble_Half",
      "rotation": 1
    },
    {
      "x": -3,
      "y": 1,
      "z": -9,
      "name": "Rock_Slate_Cobble"
    },
    {
      "x": -3,
      "y": 2,
      "z": -9,
      "name": "Rock_Slate_Cobble"
    },
    {
      "x": -3,
      "y": 3,
      "z": -9,
      "name": "Rock_Slate_Cobble"
    },
    {
      "x": -3,
      "y": 4,
      "z": -9,
      "name": "Rock_Slate_Cobble"
    },
    {
      "x": -3,
      "y": 5,
      "z": -9,
      "name": "Rock_Slate_Cobble"
    },
    {
      "x": -3,
      "y": 6,
      "z": -9,
      "name": "Rock_Slate_Cobble"
    },
    {
      "x": -3,
      "y": 7,
      "z": -9,
      "name": "Rock_Slate_Cobble"
    },
    {
      "x": -3,
      "y": 8,
      "z": -9,
      "name": "Rock_Slate_Cobble_Half"
    },
    {
      "x": -3,
      "y": 0,
      "z": -8,
      "name": "Rock_Slate_Cobble"
    },
    {
      "x": -3,
      "y": 8,
      "z": -8,
      "name": "Rock_Slate_Cobble_Half"
    },
    {
      "x": -3,
      "y": 0,
      "z": -7,
      "name": "Rock_Slate_Cobble"
    },
    {
      "x": -3,
      "y": 8,
      "z": -7,
      "name": "Rock_Slate_Cobble_Half"
    },
    {
      "x": -3,
      "y": 0,
      "z": -6,
      "name": "Rock_Slate_Cobble"
    },
    {
      "x": -3,
      "y": 1,
      "z": -6,
      "name": "Rock_Slate_Cobble"
    },
    {
      "x": -3,
      "y": 2,
      "z": -6,
      "name": "Rock_Slate_Cobble_Beam"
    },
    {
      "x": -3,
      "y": 3,
      "z": -6,
      "name": "Rock_Slate_Cobble_Beam"
    },
    {
      "x": -3,
      "y": 4,
      "z": -6,
      "name": "Rock_Slate_Cobble_Beam"
    },
    {
      "x": -3,
      "y": 5,
      "z": -6,
      "name": "Rock_Slate_Cobble_Beam"
    },
    {
      "x": -3,
      "y": 6,
      "z": -6,
      "name": "Rock_Slate_Cobble_Beam"
    },
    {
      "x": -3,
      "y": 7,
      "z": -6,
      "name": "Rock_Slate_Cobble_Beam"
    },
    {
      "x": -3,
      "y": 8,
      "z": -6,
      "name": "Rock_Slate_Cobble_Half"
    },
    {
      "x": -3,
      "y": 0,
      "z": -5,
      "name": "Rock_Slate_Cobble"
    },
    {
      "x": -3,
      "y": 8,
      "z": -5,
      "name": "Rock_Slate_Cobble_Half"
    },
    {
      "x": -3,
      "y": 0,
      "z": -4,
      "name": "Rock_Slate_Cobble"
    },
    {
      "x": -3,
      "y": 8,
      "z": -4,
      "name": "Rock_Slate_Cobble_Half"
    },
    {
      "x": -3,
      "y": 0,
      "z": -3,
      "name": "Rock_Slate_Cobble"
    },
    {
      "x": -3,
      "y": 8,
      "z": -3,
      "name": "Rock_Slate_Cobble_Half"
    },
    {
      "x": -3,
      "y": 0,
      "z": -2,
      "name": "Rock_Slate_Cobble"
    },
    {
      "x": -3,
      "y": 8,
      "z": -2,
      "name": "Rock_Slate_Cobble_Half"
    },
    {
      "x": -3,
      "y": 0,
      "z": -1,
      "name": "Rock_Slate_Cobble"
    },
    {
      "x": -3,
      "y": 8,
      "z": -1,
      "name": "Rock_Slate_Cobble_Half"
    },
    {
      "x": -3,
      "y": 0,
      "z": 0,
      "name": "Rock_Slate_Cobble"
    },
    {
      "x": -3,
      "y": 8,
      "z": 0,
      "name": "Rock_Slate_Cobble",
      "rotation": 1
    },
    {
      "x": -3,
      "y": 0,
      "z": 1,
      "name": "Rock_Slate_Cobble"
    },
    {
      "x": -3,
      "y": 8,
      "z": 1,
      "name": "Rock_Slate_Cobble_Half",
      "rotation": 1
    },
    {
      "x": -3,
      "y": 0,
      "z": 2,
      "name": "Rock_Slate_Cobble"
    },
    {
      "x": -3,
      "y": 8,
      "z": 2,
      "name": "Rock_Slate_Cobble_Half",
      "rotation": 1
    },
    {
      "x": -3,
      "y": 0,
      "z": 3,
      "name": "Rock_Slate_Cobble"
    },
    {
      "x": -3,
      "y": 8,
      "z": 3,
      "name": "Rock_Slate_Cobble_Half",
      "rotation": 1
    },
    {
      "x": -3,
      "y": 0,
      "z": 4,
      "name": "Rock_Slate_Cobble"
    },
    {
      "x": -3,
      "y": 8,
      "z": 4,
      "name": "Rock_Slate_Cobble_Half",
      "rotation": 1
    },
    {
      "x": -3,
      "y": 0,
      "z": 5,
      "name": "Rock_Slate_Cobble"
    },
    {
      "x": -3,
      "y": 8,
      "z": 5,
      "name": "Rock_Slate_Cobble_Half",
      "rotation": 1
    },
    {
      "x": -3,
      "y": 0,
      "z": 6,
      "name": "Rock_Slate_Cobble"
    },
    {
      "x": -3,
      "y": 1,
      "z": 6,
      "name": "Rock_Slate_Cobble"
    },
    {
      "x": -3,
      "y": 2,
      "z": 6,
      "name": "Rock_Slate_Cobble_Beam"
    },
    {
      "x": -3,
      "y": 3,
      "z": 6,
      "name": "Rock_Slate_Cobble_Beam"
    },
    {
      "x": -3,
      "y": 4,
      "z": 6,
      "name": "Rock_Slate_Cobble_Beam",
      "rotation": 1
    },
    {
      "x": -3,
      "y": 5,
      "z": 6,
      "name": "Rock_Slate_Cobble_Beam",
      "rotation": 1
    },
    {
      "x": -3,
      "y": 6,
      "z": 6,
      "name": "Rock_Slate_Cobble_Beam",
      "rotation": 1
    },
    {
      "x": -3,
      "y": 7,
      "z": 6,
      "name": "Rock_Slate_Cobble_Beam",
      "rotation": 1
    },
    {
      "x": -3,
      "y": 8,
      "z": 6,
      "name": "Rock_Slate_Cobble_Half",
      "rotation": 1
    },
    {
      "x": -3,
      "y": 0,
      "z": 7,
      "name": "Rock_Slate_Cobble",
      "rotation": 1
    },
    {
      "x": -3,
      "y": 8,
      "z": 7,
      "name": "Rock_Slate_Cobble_Half",
      "rotation": 1
    },
    {
      "x": -3,
      "y": 0,
      "z": 8,
      "name": "Rock_Slate_Cobble",
      "rotation": 1
    },
    {
      "x": -3,
      "y": 8,
      "z": 8,
      "name": "Rock_Slate_Cobble_Half",
      "rotation": 1
    },
    {
      "x": -3,
      "y": 1,
      "z": 9,
      "name": "Rock_Slate_Cobble",
      "rotation": 1
    },
    {
      "x": -3,
      "y": 2,
      "z": 9,
      "name": "Rock_Slate_Cobble",
      "rotation": 1
    },
    {
      "x": -3,
      "y": 3,
      "z": 9,
      "name": "Rock_Slate_Cobble",
      "rotation": 1
    },
    {
      "x": -3,
      "y": 4,
      "z": 9,
      "name": "Rock_Slate_Cobble",
      "rotation": 1
    },
    {
      "x": -3,
      "y": 5,
      "z": 9,
      "name": "Rock_Slate_Cobble",
      "rotation": 1
    },
    {
      "x": -3,
      "y": 6,
      "z": 9,
      "name": "Rock_Slate_Cobble",
      "rotation": 1
    },
    {
      "x": -3,
      "y": 7,
      "z": 9,
      "name": "Rock_Slate_Cobble",
      "rotation": 1
    },
    {
      "x": -3,
      "y": 8,
      "z": 9,
      "name": "Rock_Slate_Cobble_Half",
      "rotation": 1
    },
    {
      "x": -2,
      "y": 1,
      "z": -9,
      "name": "Rock_Slate_Cobble"
    },
    {
      "x": -2,
      "y": 2,
      "z": -9,
      "name": "Rock_Slate_Cobble_Beam",
      "rotation": 1
    },
    {
      "x": -2,
      "y": 3,
      "z": -9,
      "name": "Rock_Slate_Cobble_Beam",
      "rotation": 1
    },
    {
      "x": -2,
      "y": 4,
      "z": -9,
      "name": "Rock_Slate_Cobble_Beam",
      "rotation": 1
    },
    {
      "x": -2,
      "y": 5,
      "z": -9,
      "name": "Rock_Slate_Cobble_Beam",
      "rotation": 1
    },
    {
      "x": -2,
      "y": 6,
      "z": -9,
      "name": "Rock_Slate_Cobble_Beam",
      "rotation": 1
    },
    {
      "x": -2,
      "y": 7,
      "z": -9,
      "name": "Rock_Slate_Cobble"
    },
    {
      "x": -2,
      "y": 8,
      "z": -9,
      "name": "Rock_Slate_Cobble_Half"
    },
    {
      "x": -2,
      "y": 0,
      "z": -8,
      "name": "Rock_Slate_Cobble"
    },
    {
      "x": -2,
      "y": 8,
      "z": -8,
      "name": "Rock_Slate_Cobble_Half"
    },
    {
      "x": -2,
      "y": 0,
      "z": -7,
      "name": "Rock_Slate_Cobble"
    },
    {
      "x": -2,
      "y": 8,
      "z": -7,
      "name": "Rock_Slate_Cobble_Half"
    },
    {
      "x": -2,
      "y": 0,
      "z": -6,
      "name": "Rock_Slate_Cobble"
    },
    {
      "x": -2,
      "y": 8,
      "z": -6,
      "name": "Rock_Slate_Cobble_Half"
    },
    {
      "x": -2,
      "y": 0,
      "z": -5,
      "name": "Rock_Slate_Cobble"
    },
    {
      "x": -2,
      "y": 8,
      "z": -5,
      "name": "Rock_Slate_Cobble_Half"
    },
    {
      "x": -2,
      "y": 0,
      "z": -4,
      "name": "Rock_Slate_Cobble"
    },
    {
      "x": -2,
      "y": 8,
      "z": -4,
      "name": "Rock_Slate_Cobble_Half"
    },
    {
      "x": -2,
      "y": 0,
      "z": -3,
      "name": "Rock_Slate_Cobble"
    },
    {
      "x": -2,
      "y": 8,
      "z": -3,
      "name": "Rock_Slate_Cobble_Half"
    },
    {
      "x": -2,
      "y": 0,
      "z": -2,
      "name": "Rock_Slate_Cobble"
    },
    {
      "x": -2,
      "y": 8,
      "z": -2,
      "name": "Rock_Slate_Cobble_Half"
    },
    {
      "x": -2,
      "y": 0,
      "z": -1,
      "name": "Rock_Slate_Cobble"
    },
    {
      "x": -2,
      "y": 8,
      "z": -1,
      "name": "Rock_Slate_Cobble_Half"
    },
    {
      "x": -2,
      "y": 0,
      "z": 0,
      "name": "Rock_Slate_Cobble"
    },
    {
      "x": -2,
      "y": 8,
      "z": 0,
      "name": "Rock_Slate_Cobble",
      "rotation": 1
    },
    {
      "x": -2,
      "y": 0,
      "z": 1,
      "name": "Rock_Slate_Cobble"
    },
    {
      "x": -2,
      "y": 8,
      "z": 1,
      "name": "Rock_Slate_Cobble_Half",
      "rotation": 1
    },
    {
      "x": -2,
      "y": 0,
      "z": 2,
      "name": "Rock_Slate_Cobble"
    },
    {
      "x": -2,
      "y": 8,
      "z": 2,
      "name": "Rock_Slate_Cobble_Half",
      "rotation": 1
    },
    {
      "x": -2,
      "y": 0,
      "z": 3,
      "name": "Rock_Slate_Cobble"
    },
    {
      "x": -2,
      "y": 8,
      "z": 3,
      "name": "Rock_Slate_Cobble_Half",
      "rotation": 1
    },
    {
      "x": -2,
      "y": 0,
      "z": 4,
      "name": "Rock_Slate_Cobble"
    },
    {
      "x": -2,
      "y": 8,
      "z": 4,
      "name": "Rock_Slate_Cobble_Half",
      "rotation": 1
    },
    {
      "x": -2,
      "y": 0,
      "z": 5,
      "name": "Rock_Slate_Cobble",
      "rotation": 1
    },
    {
      "x": -2,
      "y": 8,
      "z": 5,
      "name": "Rock_Slate_Cobble_Half",
      "rotation": 1
    },
    {
      "x": -2,
      "y": 0,
      "z": 6,
      "name": "Rock_Slate_Cobble",
      "rotation": 1
    },
    {
      "x": -2,
      "y": 8,
      "z": 6,
      "name": "Rock_Slate_Cobble_Half",
      "rotation": 1
    },
    {
      "x": -2,
      "y": 0,
      "z": 7,
      "name": "Rock_Slate_Cobble",
      "rotation": 1
    },
    {
      "x": -2,
      "y": 8,
      "z": 7,
      "name": "Rock_Slate_Cobble_Half",
      "rotation": 1
    },
    {
      "x": -2,
      "y": 0,
      "z": 8,
      "name": "Rock_Slate_Cobble",
      "rotation": 1
    },
    {
      "x": -2,
      "y": 8,
      "z": 8,
      "name": "Rock_Slate_Cobble_Half",
      "rotation": 1
    },
    {
      "x": -2,
      "y": 1,
      "z": 9,
      "name": "Rock_Slate_Cobble",
      "rotation": 1
    },
    {
      "x": -2,
      "y": 2,
      "z": 9,
      "name": "Rock_Slate_Cobble_Beam",
      "rotation": 1
    },
    {
      "x": -2,
      "y": 3,
      "z": 9,
      "name": "Rock_Slate_Cobble_Beam",
      "rotation": 1
    },
    {
      "x": -2,
      "y": 4,
      "z": 9,
      "name": "Rock_Slate_Cobble_Beam",
      "rotation": 1
    },
    {
      "x": -2,
      "y": 5,
      "z": 9,
      "name": "Rock_Slate_Cobble_Beam",
      "rotation": 1
    },
    {
      "x": -2,
      "y": 6,
      "z": 9,
      "name": "Rock_Slate_Cobble_Beam",
      "rotation": 1
    },
    {
      "x": -2,
      "y": 7,
      "z": 9,
      "name": "Rock_Slate_Cobble",
      "rotation": 1
    },
    {
      "x": -2,
      "y": 8,
      "z": 9,
      "name": "Rock_Slate_Cobble_Half",
      "rotation": 1
    },
    {
      "x": -1,
      "y": 1,
      "z": -9,
      "name": "Rock_Slate_Cobble"
    },
    {
      "x": -1,
      "y": 7,
      "z": -9,
      "name": "Rock_Slate_Stalactite_Small",
      "rotation": 9
    },
    {
      "x": -1,
      "y": 8,
      "z": -9,
      "name": "Rock_Slate_Cobble_Half"
    },
    {
      "x": -1,
      "y": 0,
      "z": -8,
      "name": "Rock_Slate_Cobble"
    },
    {
      "x": -1,
      "y": 8,
      "z": -8,
      "name": "Rock_Slate_Cobble_Half"
    },
    {
      "x": -1,
      "y": 0,
      "z": -7,
      "name": "Rock_Slate_Cobble"
    },
    {
      "x": -1,
      "y": 8,
      "z": -7,
      "name": "Rock_Slate_Cobble_Half"
    },
    {
      "x": -1,
      "y": 0,
      "z": -6,
      "name": "Rock_Slate_Cobble"
    },
    {
      "x": -1,
      "y": 8,
      "z": -6,
      "name": "Rock_Slate_Cobble_Half"
    },
    {
      "x": -1,
      "y": 0,
      "z": -5,
      "name": "Rock_Slate_Cobble"
    },
    {
      "x": -1,
      "y": 8,
      "z": -5,
      "name": "Rock_Slate_Cobble_Half"
    },
    {
      "x": -1,
      "y": 0,
      "z": -4,
      "name": "Rock_Slate_Cobble"
    },
    {
      "x": -1,
      "y": 8,
      "z": -4,
      "name": "Rock_Slate_Cobble_Half"
    },
    {
      "x": -1,
      "y": 0,
      "z": -3,
      "name": "Rock_Slate_Cobble"
    },
    {
      "x": -1,
      "y": 8,
      "z": -3,
      "name": "Rock_Slate_Cobble_Half"
    },
    {
      "x": -1,
      "y": 0,
      "z": -2,
      "name": "Rock_Slate_Cobble"
    },
    {
      "x": -1,
      "y": 8,
      "z": -2,
      "name": "Rock_Slate_Cobble_Half"
    },
    {
      "x": -1,
      "y": 0,
      "z": -1,
      "name": "Rock_Slate_Cobble"
    },
    {
      "x": -1,
      "y": 8,
      "z": -1,
      "name": "Rock_Slate_Cobble_Half"
    },
    {
      "x": -1,
      "y": 0,
      "z": 0,
      "name": "Rock_Slate_Cobble"
    },
    {
      "x": -1,
      "y": 8,
      "z": 0,
      "name": "Rock_Slate_Cobble",
      "rotation": 1
    },
    {
      "x": -1,
      "y": 0,
      "z": 1,
      "name": "Rock_Slate_Cobble"
    },
    {
      "x": -1,
      "y": 8,
      "z": 1,
      "name": "Rock_Slate_Cobble_Half",
      "rotation": 1
    },
    {
      "x": -1,
      "y": 0,
      "z": 2,
      "name": "Rock_Slate_Cobble"
    },
    {
      "x": -1,
      "y": 8,
      "z": 2,
      "name": "Rock_Slate_Cobble_Half",
      "rotation": 1
    },
    {
      "x": -1,
      "y": 0,
      "z": 3,
      "name": "Rock_Slate_Cobble"
    },
    {
      "x": -1,
      "y": 8,
      "z": 3,
      "name": "Rock_Slate_Cobble_Half",
      "rotation": 1
    },
    {
      "x": -1,
      "y": 0,
      "z": 4,
      "name": "Rock_Slate_Cobble"
    },
    {
      "x": -1,
      "y": 8,
      "z": 4,
      "name": "Rock_Slate_Cobble_Half",
      "rotation": 1
    },
    {
      "x": -1,
      "y": 0,
      "z": 5,
      "name": "Rock_Slate_Cobble"
    },
    {
      "x": -1,
      "y": 8,
      "z": 5,
      "name": "Rock_Slate_Cobble_Half",
      "rotation": 1
    },
    {
      "x": -1,
      "y": 0,
      "z": 6,
      "name": "Rock_Slate_Cobble"
    },
    {
      "x": -1,
      "y": 8,
      "z": 6,
      "name": "Rock_Slate_Cobble_Half",
      "rotation": 1
    },
    {
      "x": -1,
      "y": 0,
      "z": 7,
      "name": "Rock_Slate_Cobble",
      "rotation": 1
    },
    {
      "x": -1,
      "y": 8,
      "z": 7,
      "name": "Rock_Slate_Cobble_Half",
      "rotation": 1
    },
    {
      "x": -1,
      "y": 0,
      "z": 8,
      "name": "Rock_Slate_Cobble",
      "rotation": 1
    },
    {
      "x": -1,
      "y": 8,
      "z": 8,
      "name": "Rock_Slate_Cobble_Half",
      "rotation": 1
    },
    {
      "x": -1,
      "y": 1,
      "z": 9,
      "name": "Rock_Slate_Cobble",
      "rotation": 1
    },
    {
      "x": -1,
      "y": 7,
      "z": 9,
      "name": "Rock_Slate_Stalactite_Small",
      "rotation": 9
    },
    {
      "x": -1,
      "y": 8,
      "z": 9,
      "name": "Rock_Slate_Cobble_Half",
      "rotation": 1
    },
    {
      "x": 0,
      "y": 1,
      "z": -9,
      "name": "Rock_Bedrock",
      "rotation": 1
    },
    {
      "x": 0,
      "y": 7,
      "z": -9,
      "name": "Rock_Slate_Stalactite_Small",
      "rotation": 9
    },
    {
      "x": 0,
      "y": 8,
      "z": -9,
      "name": "Rock_Slate_Cobble",
      "rotation": 1
    },
    {
      "x": 0,
      "y": 0,
      "z": -8,
      "name": "Rock_Slate_Cobble"
    },
    {
      "x": 0,
      "y": 8,
      "z": -8,
      "name": "Rock_Slate_Cobble",
      "rotation": 1
    },
    {
      "x": 0,
      "y": 0,
      "z": -7,
      "name": "Rock_Slate_Cobble"
    },
    {
      "x": 0,
      "y": 8,
      "z": -7,
      "name": "Rock_Slate_Cobble",
      "rotation": 1
    },
    {
      "x": 0,
      "y": 0,
      "z": -6,
      "name": "Rock_Slate_Cobble"
    },
    {
      "x": 0,
      "y": 8,
      "z": -6,
      "name": "Rock_Slate_Cobble",
      "rotation": 1
    },
    {
      "x": 0,
      "y": 0,
      "z": -5,
      "name": "Rock_Slate_Cobble"
    },
    {
      "x": 0,
      "y": 8,
      "z": -5,
      "name": "Rock_Slate_Cobble",
      "rotation": 1
    },
    {
      "x": 0,
      "y": 0,
      "z": -4,
      "name": "Rock_Slate_Cobble"
    },
    {
      "x": 0,
      "y": 8,
      "z": -4,
      "name": "Rock_Slate_Cobble",
      "rotation": 1
    },
    {
      "x": 0,
      "y": 0,
      "z": -3,
      "name": "Rock_Slate_Cobble"
    },
    {
      "x": 0,
      "y": 8,
      "z": -3,
      "name": "Rock_Slate_Cobble",
      "rotation": 1
    },
    {
      "x": 0,
      "y": 0,
      "z": -2,
      "name": "Rock_Slate_Cobble"
    },
    {
      "x": 0,
      "y": 8,
      "z": -2,
      "name": "Rock_Slate_Cobble",
      "rotation": 1
    },
    {
      "x": 0,
      "y": 0,
      "z": -1,
      "name": "Rock_Slate_Cobble"
    },
    {
      "x": 0,
      "y": 8,
      "z": -1,
      "name": "Rock_Slate_Cobble",
      "rotation": 1
    },
    {
      "x": 0,
      "y": 0,
      "z": 0,
      "name": "Rock_Slate_Cobble"
    },
    {
      "x": 0,
      "y": 8,
      "z": 0,
      "name": "Rock_Slate_Cobble",
      "rotation": 1
    },
    {
      "x": 0,
      "y": 0,
      "z": 1,
      "name": "Rock_Slate_Cobble"
    },
    {
      "x": 0,
      "y": 8,
      "z": 1,
      "name": "Rock_Slate_Cobble",
      "rotation": 1
    },
    {
      "x": 0,
      "y": 0,
      "z": 2,
      "name": "Rock_Slate_Cobble"
    },
    {
      "x": 0,
      "y": 8,
      "z": 2,
      "name": "Rock_Slate_Cobble",
      "rotation": 1
    },
    {
      "x": 0,
      "y": 0,
      "z": 3,
      "name": "Rock_Slate_Cobble"
    },
    {
      "x": 0,
      "y": 8,
      "z": 3,
      "name": "Rock_Slate_Cobble",
      "rotation": 1
    },
    {
      "x": 0,
      "y": 0,
      "z": 4,
      "name": "Rock_Slate_Cobble"
    },
    {
      "x": 0,
      "y": 8,
      "z": 4,
      "name": "Rock_Slate_Cobble",
      "rotation": 1
    },
    {
      "x": 0,
      "y": 0,
      "z": 5,
      "name": "Rock_Slate_Cobble"
    },
    {
      "x": 0,
      "y": 8,
      "z": 5,
      "name": "Rock_Slate_Cobble",
      "rotation": 1
    },
    {
      "x": 0,
      "y": 0,
      "z": 6,
      "name": "Rock_Slate_Cobble"
    },
    {
      "x": 0,
      "y": 8,
      "z": 6,
      "name": "Rock_Slate_Cobble",
      "rotation": 1
    },
    {
      "x": 0,
      "y": 0,
      "z": 7,
      "name": "Rock_Slate_Cobble"
    },
    {
      "x": 0,
      "y": 8,
      "z": 7,
      "name": "Rock_Slate_Cobble",
      "rotation": 1
    },
    {
      "x": 0,
      "y": 0,
      "z": 8,
      "name": "Rock_Slate_Cobble"
    },
    {
      "x": 0,
      "y": 8,
      "z": 8,
      "name": "Rock_Slate_Cobble",
      "rotation": 1
    },
    {
      "x": 0,
      "y": 1,
      "z": 9,
      "name": "Rock_Bedrock",
      "rotation": 1
    },
    {
      "x": 0,
      "y": 7,
      "z": 9,
      "name": "Rock_Slate_Stalactite_Small",
      "rotation": 9
    },
    {
      "x": 0,
      "y": 8,
      "z": 9,
      "name": "Rock_Slate_Cobble",
      "rotation": 1
    },
    {
      "x": 1,
      "y": 1,
      "z": -9,
      "name": "Rock_Slate_Cobble",
      "rotation": 3
    },
    {
      "x": 1,
      "y": 7,
      "z": -9,
      "name": "Rock_Slate_Stalactite_Small",
      "rotation": 9
    },
    {
      "x": 1,
      "y": 8,
      "z": -9,
      "name": "Rock_Slate_Cobble_Half",
      "rotation": 3
    },
    {
      "x": 1,
      "y": 0,
      "z": -8,
      "name": "Rock_Slate_Cobble",
      "rotation": 3
    },
    {
      "x": 1,
      "y": 8,
      "z": -8,
      "name": "Rock_Slate_Cobble_Half",
      "rotation": 3
    },
    {
      "x": 1,
      "y": 0,
      "z": -7,
      "name": "Rock_Slate_Cobble",
      "rotation": 3
    },
    {
      "x": 1,
      "y": 8,
      "z": -7,
      "name": "Rock_Slate_Cobble_Half",
      "rotation": 3
    },
    {
      "x": 1,
      "y": 0,
      "z": -6,
      "name": "Rock_Slate_Cobble"
    },
    {
      "x": 1,
      "y": 8,
      "z": -6,
      "name": "Rock_Slate_Cobble_Half",
      "rotation": 3
    },
    {
      "x": 1,
      "y": 0,
      "z": -5,
      "name": "Rock_Slate_Cobble"
    },
    {
      "x": 1,
      "y": 8,
      "z": -5,
      "name": "Rock_Slate_Cobble_Half",
      "rotation": 3
    },
    {
      "x": 1,
      "y": 0,
      "z": -4,
      "name": "Rock_Slate_Cobble"
    },
    {
      "x": 1,
      "y": 8,
      "z": -4,
      "name": "Rock_Slate_Cobble_Half",
      "rotation": 3
    },
    {
      "x": 1,
      "y": 0,
      "z": -3,
      "name": "Rock_Slate_Cobble"
    },
    {
      "x": 1,
      "y": 8,
      "z": -3,
      "name": "Rock_Slate_Cobble_Half",
      "rotation": 3
    },
    {
      "x": 1,
      "y": 0,
      "z": -2,
      "name": "Rock_Slate_Cobble"
    },
    {
      "x": 1,
      "y": 8,
      "z": -2,
      "name": "Rock_Slate_Cobble_Half",
      "rotation": 3
    },
    {
      "x": 1,
      "y": 0,
      "z": -1,
      "name": "Rock_Slate_Cobble"
    },
    {
      "x": 1,
      "y": 8,
      "z": -1,
      "name": "Rock_Slate_Cobble_Half",
      "rotation": 3
    },
    {
      "x": 1,
      "y": 0,
      "z": 0,
      "name": "Rock_Slate_Cobble"
    },
    {
      "x": 1,
      "y": 8,
      "z": 0,
      "name": "Rock_Slate_Cobble",
      "rotation": 1
    },
    {
      "x": 1,
      "y": 0,
      "z": 1,
      "name": "Rock_Slate_Cobble"
    },
    {
      "x": 1,
      "y": 8,
      "z": 1,
      "name": "Rock_Slate_Cobble_Half",
      "rotation": 2
    },
    {
      "x": 1,
      "y": 0,
      "z": 2,
      "name": "Rock_Slate_Cobble"
    },
    {
      "x": 1,
      "y": 8,
      "z": 2,
      "name": "Rock_Slate_Cobble_Half",
      "rotation": 2
    },
    {
      "x": 1,
      "y": 0,
      "z": 3,
      "name": "Rock_Slate_Cobble"
    },
    {
      "x": 1,
      "y": 8,
      "z": 3,
      "name": "Rock_Slate_Cobble_Half",
      "rotation": 2
    },
    {
      "x": 1,
      "y": 0,
      "z": 4,
      "name": "Rock_Slate_Cobble"
    },
    {
      "x": 1,
      "y": 8,
      "z": 4,
      "name": "Rock_Slate_Cobble_Half",
      "rotation": 2
    },
    {
      "x": 1,
      "y": 0,
      "z": 5,
      "name": "Rock_Slate_Cobble"
    },
    {
      "x": 1,
      "y": 8,
      "z": 5,
      "name": "Rock_Slate_Cobble_Half",
      "rotation": 2
    },
    {
      "x": 1,
      "y": 0,
      "z": 6,
      "name": "Rock_Slate_Cobble",
      "rotation": 2
    },
    {
      "x": 1,
      "y": 8,
      "z": 6,
      "name": "Rock_Slate_Cobble_Half",
      "rotation": 2
    },
    {
      "x": 1,
      "y": 0,
      "z": 7,
      "name": "Rock_Slate_Cobble",
      "rotation": 2
    },
    {
      "x": 1,
      "y": 8,
      "z": 7,
      "name": "Rock_Slate_Cobble_Half",
      "rotation": 2
    },
    {
      "x": 1,
      "y": 0,
      "z": 8,
      "name": "Rock_Slate_Cobble",
      "rotation": 2
    },
    {
      "x": 1,
      "y": 8,
      "z": 8,
      "name": "Rock_Slate_Cobble_Half",
      "rotation": 2
    },
    {
      "x": 1,
      "y": 1,
      "z": 9,
      "name": "Rock_Slate_Cobble",
      "rotation": 2
    },
    {
      "x": 1,
      "y": 7,
      "z": 9,
      "name": "Rock_Slate_Stalactite_Small",
      "rotation": 9
    },
    {
      "x": 1,
      "y": 8,
      "z": 9,
      "name": "Rock_Slate_Cobble_Half",
      "rotation": 2
    },
    {
      "x": 2,
      "y": 1,
      "z": -9,
      "name": "Rock_Slate_Cobble",
      "rotation": 3
    },
    {
      "x": 2,
      "y": 2,
      "z": -9,
      "name": "Rock_Slate_Cobble_Beam",
      "rotation": 1
    },
    {
      "x": 2,
      "y": 3,
      "z": -9,
      "name": "Rock_Slate_Cobble_Beam",
      "rotation": 1
    },
    {
      "x": 2,
      "y": 4,
      "z": -9,
      "name": "Rock_Slate_Cobble_Beam",
      "rotation": 1
    },
    {
      "x": 2,
      "y": 5,
      "z": -9,
      "name": "Rock_Slate_Cobble_Beam",
      "rotation": 1
    },
    {
      "x": 2,
      "y": 6,
      "z": -9,
      "name": "Rock_Slate_Cobble_Beam",
      "rotation": 1
    },
    {
      "x": 2,
      "y": 7,
      "z": -9,
      "name": "Rock_Slate_Cobble",
      "rotation": 1
    },
    {
      "x": 2,
      "y": 8,
      "z": -9,
      "name": "Rock_Slate_Cobble_Half",
      "rotation": 3
    },
    {
      "x": 2,
      "y": 0,
      "z": -8,
      "name": "Rock_Slate_Cobble",
      "rotation": 3
    },
    {
      "x": 2,
      "y": 8,
      "z": -8,
      "name": "Rock_Slate_Cobble_Half",
      "rotation": 3
    },
    {
      "x": 2,
      "y": 0,
      "z": -7,
      "name": "Rock_Slate_Cobble",
      "rotation": 3
    },
    {
      "x": 2,
      "y": 8,
      "z": -7,
      "name": "Rock_Slate_Cobble_Half",
      "rotation": 3
    },
    {
      "x": 2,
      "y": 0,
      "z": -6,
      "name": "Rock_Slate_Cobble",
      "rotation": 3
    },
    {
      "x": 2,
      "y": 8,
      "z": -6,
      "name": "Rock_Slate_Cobble_Half",
      "rotation": 3
    },
    {
      "x": 2,
      "y": 0,
      "z": -5,
      "name": "Rock_Slate_Cobble",
      "rotation": 3
    },
    {
      "x": 2,
      "y": 8,
      "z": -5,
      "name": "Rock_Slate_Cobble_Half",
      "rotation": 3
    },
    {
      "x": 2,
      "y": 0,
      "z": -4,
      "name": "Rock_Slate_Cobble"
    },
    {
      "x": 2,
      "y": 8,
      "z": -4,
      "name": "Rock_Slate_Cobble_Half",
      "rotation": 3
    },
    {
      "x": 2,
      "y": 0,
      "z": -3,
      "name": "Rock_Slate_Cobble"
    },
    {
      "x": 2,
      "y": 8,
      "z": -3,
      "name": "Rock_Slate_Cobble_Half",
      "rotation": 3
    },
    {
      "x": 2,
      "y": 0,
      "z": -2,
      "name": "Rock_Slate_Cobble"
    },
    {
      "x": 2,
      "y": 8,
      "z": -2,
      "name": "Rock_Slate_Cobble_Half",
      "rotation": 3
    },
    {
      "x": 2,
      "y": 0,
      "z": -1,
      "name": "Rock_Slate_Cobble"
    },
    {
      "x": 2,
      "y": 8,
      "z": -1,
      "name": "Rock_Slate_Cobble_Half",
      "rotation": 3
    },
    {
      "x": 2,
      "y": 0,
      "z": 0,
      "name": "Rock_Slate_Cobble"
    },
    {
      "x": 2,
      "y": 8,
      "z": 0,
      "name": "Rock_Slate_Cobble",
      "rotation": 1
    },
    {
      "x": 2,
      "y": 0,
      "z": 1,
      "name": "Rock_Slate_Cobble"
    },
    {
      "x": 2,
      "y": 8,
      "z": 1,
      "name": "Rock_Slate_Cobble_Half",
      "rotation": 2
    },
    {
      "x": 2,
      "y": 0,
      "z": 2,
      "name": "Rock_Slate_Cobble"
    },
    {
      "x": 2,
      "y": 8,
      "z": 2,
      "name": "Rock_Slate_Cobble_Half",
      "rotation": 2
    },
    {
      "x": 2,
      "y": 0,
      "z": 3,
      "name": "Rock_Slate_Cobble"
    },
    {
      "x": 2,
      "y": 8,
      "z": 3,
      "name": "Rock_Slate_Cobble_Half",
      "rotation": 2
    },
    {
      "x": 2,
      "y": 0,
      "z": 4,
      "name": "Rock_Slate_Cobble"
    },
    {
      "x": 2,
      "y": 8,
      "z": 4,
      "name": "Rock_Slate_Cobble_Half",
      "rotation": 2
    },
    {
      "x": 2,
      "y": 0,
      "z": 5,
      "name": "Rock_Slate_Cobble"
    },
    {
      "x": 2,
      "y": 8,
      "z": 5,
      "name": "Rock_Slate_Cobble_Half",
      "rotation": 2
    },
    {
      "x": 2,
      "y": 0,
      "z": 6,
      "name": "Rock_Slate_Cobble",
      "rotation": 2
    },
    {
      "x": 2,
      "y": 8,
      "z": 6,
      "name": "Rock_Slate_Cobble_Half",
      "rotation": 2
    },
    {
      "x": 2,
      "y": 0,
      "z": 7,
      "name": "Rock_Slate_Cobble",
      "rotation": 2
    },
    {
      "x": 2,
      "y": 8,
      "z": 7,
      "name": "Rock_Slate_Cobble_Half",
      "rotation": 2
    },
    {
      "x": 2,
      "y": 0,
      "z": 8,
      "name": "Rock_Slate_Cobble",
      "rotation": 2
    },
    {
      "x": 2,
      "y": 8,
      "z": 8,
      "name": "Rock_Slate_Cobble_Half",
      "rotation": 2
    },
    {
      "x": 2,
      "y": 1,
      "z": 9,
      "name": "Rock_Slate_Cobble",
      "rotation": 2
    },
    {
      "x": 2,
      "y": 2,
      "z": 9,
      "name": "Rock_Slate_Cobble_Beam",
      "rotation": 1
    },
    {
      "x": 2,
      "y": 3,
      "z": 9,
      "name": "Rock_Slate_Cobble_Beam",
      "rotation": 1
    },
    {
      "x": 2,
      "y": 4,
      "z": 9,
      "name": "Rock_Slate_Cobble_Beam",
      "rotation": 1
    },
    {
      "x": 2,
      "y": 5,
      "z": 9,
      "name": "Rock_Slate_Cobble_Beam",
      "rotation": 1
    },
    {
      "x": 2,
      "y": 6,
      "z": 9,
      "name": "Rock_Slate_Cobble_Beam",
      "rotation": 1
    },
    {
      "x": 2,
      "y": 7,
      "z": 9,
      "name": "Rock_Slate_Cobble",
      "rotation": 2
    },
    {
      "x": 2,
      "y": 8,
      "z": 9,
      "name": "Rock_Slate_Cobble_Half",
      "rotation": 2
    },
    {
      "x": 3,
      "y": 1,
      "z": -9,
      "name": "Rock_Slate_Cobble",
      "rotation": 3
    },
    {
      "x": 3,
      "y": 2,
      "z": -9,
      "name": "Rock_Slate_Cobble",
      "rotation": 3
    },
    {
      "x": 3,
      "y": 3,
      "z": -9,
      "name": "Rock_Slate_Cobble",
      "rotation": 3
    },
    {
      "x": 3,
      "y": 4,
      "z": -9,
      "name": "Rock_Slate_Cobble",
      "rotation": 3
    },
    {
      "x": 3,
      "y": 5,
      "z": -9,
      "name": "Rock_Slate_Cobble",
      "rotation": 3
    },
    {
      "x": 3,
      "y": 6,
      "z": -9,
      "name": "Rock_Slate_Cobble",
      "rotation": 3
    },
    {
      "x": 3,
      "y": 7,
      "z": -9,
      "name": "Rock_Slate_Cobble",
      "rotation": 3
    },
    {
      "x": 3,
      "y": 8,
      "z": -9,
      "name": "Rock_Slate_Cobble_Half",
      "rotation": 3
    },
    {
      "x": 3,
      "y": 0,
      "z": -8,
      "name": "Rock_Slate_Cobble",
      "rotation": 3
    },
    {
      "x": 3,
      "y": 8,
      "z": -8,
      "name": "Rock_Slate_Cobble_Half",
      "rotation": 3
    },
    {
      "x": 3,
      "y": 0,
      "z": -7,
      "name": "Rock_Slate_Cobble",
      "rotation": 3
    },
    {
      "x": 3,
      "y": 8,
      "z": -7,
      "name": "Rock_Slate_Cobble_Half",
      "rotation": 3
    },
    {
      "x": 3,
      "y": 0,
      "z": -6,
      "name": "Rock_Slate_Cobble",
      "rotation": 3
    },
    {
      "x": 3,
      "y": 1,
      "z": -6,
      "name": "Rock_Slate_Cobble",
      "rotation": 3
    },
    {
      "x": 3,
      "y": 2,
      "z": -6,
      "name": "Rock_Slate_Cobble_Beam",
      "rotation": 3
    },
    {
      "x": 3,
      "y": 3,
      "z": -6,
      "name": "Rock_Slate_Cobble_Beam",
      "rotation": 3
    },
    {
      "x": 3,
      "y": 4,
      "z": -6,
      "name": "Rock_Slate_Cobble_Beam",
      "rotation": 3
    },
    {
      "x": 3,
      "y": 5,
      "z": -6,
      "name": "Rock_Slate_Cobble_Beam",
      "rotation": 3
    },
    {
      "x": 3,
      "y": 6,
      "z": -6,
      "name": "Rock_Slate_Cobble_Beam",
      "rotation": 3
    },
    {
      "x": 3,
      "y": 7,
      "z": -6,
      "name": "Rock_Slate_Cobble_Beam",
      "rotation": 3
    },
    {
      "x": 3,
      "y": 8,
      "z": -6,
      "name": "Rock_Slate_Cobble_Half",
      "rotation": 3
    },
    {
      "x": 3,
      "y": 0,
      "z": -5,
      "name": "Rock_Slate_Cobble",
      "rotation": 3
    },
    {
      "x": 3,
      "y": 8,
      "z": -5,
      "name": "Rock_Slate_Cobble_Half",
      "rotation": 3
    },
    {
      "x": 3,
      "y": 0,
      "z": -4,
      "name": "Rock_Slate_Cobble"
    },
    {
      "x": 3,
      "y": 8,
      "z": -4,
      "name": "Rock_Slate_Cobble_Half",
      "rotation": 3
    },
    {
      "x": 3,
      "y": 0,
      "z": -3,
      "name": "Rock_Slate_Cobble"
    },
    {
      "x": 3,
      "y": 8,
      "z": -3,
      "name": "Rock_Slate_Cobble_Half",
      "rotation": 3
    },
    {
      "x": 3,
      "y": 0,
      "z": -2,
      "name": "Rock_Slate_Cobble"
    },
    {
      "x": 3,
      "y": 8,
      "z": -2,
      "name": "Rock_Slate_Cobble_Half",
      "rotation": 3
    },
    {
      "x": 3,
      "y": 0,
      "z": -1,
      "name": "Rock_Slate_Cobble"
    },
    {
      "x": 3,
      "y": 8,
      "z": -1,
      "name": "Rock_Slate_Cobble_Half",
      "rotation": 3
    },
    {
      "x": 3,
      "y": 0,
      "z": 0,
      "name": "Rock_Slate_Cobble"
    },
    {
      "x": 3,
      "y": 8,
      "z": 0,
      "name": "Rock_Slate_Cobble",
      "rotation": 1
    },
    {
      "x": 3,
      "y": 0,
      "z": 1,
      "name": "Rock_Slate_Cobble"
    },
    {
      "x": 3,
      "y": 8,
      "z": 1,
      "name": "Rock_Slate_Cobble_Half",
      "rotation": 2
    },
    {
      "x": 3,
      "y": 0,
      "z": 2,
      "name": "Rock_Slate_Cobble"
    },
    {
      "x": 3,
      "y": 8,
      "z": 2,
      "name": "Rock_Slate_Cobble_Half",
      "rotation": 2
    },
    {
      "x": 3,
      "y": 0,
      "z": 3,
      "name": "Rock_Slate_Cobble"
    },
    {
      "x": 3,
      "y": 8,
      "z": 3,
      "name": "Rock_Slate_Cobble_Half",
      "rotation": 2
    },
    {
      "x": 3,
      "y": 0,
      "z": 4,
      "name": "Rock_Slate_Cobble"
    },
    {
      "x": 3,
      "y": 8,
      "z": 4,
      "name": "Rock_Slate_Cobble_Half",
      "rotation": 2
    },
    {
      "x": 3,
      "y": 0,
      "z": 5,
      "name": "Rock_Slate_Cobble"
    },
    {
      "x": 3,
      "y": 8,
      "z": 5,
      "name": "Rock_Slate_Cobble_Half",
      "rotation": 2
    },
    {
      "x": 3,
      "y": 0,
      "z": 6,
      "name": "Rock_Slate_Cobble",
      "rotation": 2
    },
    {
      "x": 3,
      "y": 1,
      "z": 6,
      "name": "Rock_Slate_Cobble",
      "rotation": 2
    },
    {
      "x": 3,
      "y": 2,
      "z": 6,
      "name": "Rock_Slate_Cobble_Beam",
      "rotation": 2
    },
    {
      "x": 3,
      "y": 3,
      "z": 6,
      "name": "Rock_Slate_Cobble_Beam",
      "rotation": 2
    },
    {
      "x": 3,
      "y": 4,
      "z": 6,
      "name": "Rock_Slate_Cobble_Beam",
      "rotation": 2
    },
    {
      "x": 3,
      "y": 5,
      "z": 6,
      "name": "Rock_Slate_Cobble_Beam",
      "rotation": 2
    },
    {
      "x": 3,
      "y": 6,
      "z": 6,
      "name": "Rock_Slate_Cobble_Beam",
      "rotation": 2
    },
    {
      "x": 3,
      "y": 7,
      "z": 6,
      "name": "Rock_Slate_Cobble_Beam",
      "rotation": 2
    },
    {
      "x": 3,
      "y": 8,
      "z": 6,
      "name": "Rock_Slate_Cobble_Half",
      "rotation": 2
    },
    {
      "x": 3,
      "y": 0,
      "z": 7,
      "name": "Rock_Slate_Cobble",
      "rotation": 2
    },
    {
      "x": 3,
      "y": 8,
      "z": 7,
      "name": "Rock_Slate_Cobble_Half",
      "rotation": 2
    },
    {
      "x": 3,
      "y": 0,
      "z": 8,
      "name": "Rock_Slate_Cobble",
      "rotation": 2
    },
    {
      "x": 3,
      "y": 8,
      "z": 8,
      "name": "Rock_Slate_Cobble_Half",
      "rotation": 2
    },
    {
      "x": 3,
      "y": 1,
      "z": 9,
      "name": "Rock_Slate_Cobble",
      "rotation": 2
    },
    {
      "x": 3,
      "y": 2,
      "z": 9,
      "name": "Rock_Slate_Cobble",
      "rotation": 2
    },
    {
      "x": 3,
      "y": 3,
      "z": 9,
      "name": "Rock_Slate_Cobble",
      "rotation": 2
    },
    {
      "x": 3,
      "y": 4,
      "z": 9,
      "name": "Rock_Slate_Cobble",
      "rotation": 2
    },
    {
      "x": 3,
      "y": 5,
      "z": 9,
      "name": "Rock_Slate_Cobble",
      "rotation": 2
    },
    {
      "x": 3,
      "y": 6,
      "z": 9,
      "name": "Rock_Slate_Cobble",
      "rotation": 2
    },
    {
      "x": 3,
      "y": 7,
      "z": 9,
      "name": "Rock_Slate_Cobble",
      "rotation": 2
    },
    {
      "x": 3,
      "y": 8,
      "z": 9,
      "name": "Rock_Slate_Cobble_Half",
      "rotation": 2
    },
    {
      "x": 4,
      "y": 1,
      "z": -9,
      "name": "Rock_Slate_Cobble",
      "rotation": 3
    },
    {
      "x": 4,
      "y": 2,
      "z": -9,
      "name": "Rock_Slate_Cobble",
      "rotation": 3
    },
    {
      "x": 4,
      "y": 3,
      "z": -9,
      "name": "Rock_Slate_Cobble",
      "rotation": 3
    },
    {
      "x": 4,
      "y": 4,
      "z": -9,
      "name": "Rock_Slate_Cobble",
      "rotation": 3
    },
    {
      "x": 4,
      "y": 5,
      "z": -9,
      "name": "Rock_Slate_Cobble",
      "rotation": 3
    },
    {
      "x": 4,
      "y": 6,
      "z": -9,
      "name": "Rock_Slate_Cobble",
      "rotation": 3
    },
    {
      "x": 4,
      "y": 7,
      "z": -9,
      "name": "Rock_Slate_Cobble",
      "rotation": 3
    },
    {
      "x": 4,
      "y": 8,
      "z": -9,
      "name": "Rock_Slate_Cobble_Half",
      "rotation": 3
    },
    {
      "x": 4,
      "y": 0,
      "z": -8,
      "name": "Rock_Slate_Cobble",
      "rotation": 3
    },
    {
      "x": 4,
      "y": 8,
      "z": -8,
      "name": "Rock_Slate_Cobble_Half",
      "rotation": 3
    },
    {
      "x": 4,
      "y": 0,
      "z": -7,
      "name": "Rock_Slate_Cobble",
      "rotation": 3
    },
    {
      "x": 4,
      "y": 8,
      "z": -7,
      "name": "Rock_Slate_Cobble_Half",
      "rotation": 3
    },
    {
      "x": 4,
      "y": 0,
      "z": -6,
      "name": "Rock_Slate_Cobble",
      "rotation": 3
    },
    {
      "x": 4,
      "y": 8,
      "z": -6,
      "name": "Rock_Slate_Cobble_Half",
      "rotation": 3
    },
    {
      "x": 4,
      "y": 0,
      "z": -5,
      "name": "Rock_Slate_Cobble",
      "rotation": 3
    },
    {
      "x": 4,
      "y": 8,
      "z": -5,
      "name": "Rock_Slate_Cobble_Half",
      "rotation": 3
    },
    {
      "x": 4,
      "y": 0,
      "z": -4,
      "name": "Rock_Slate_Cobble"
    },
    {
      "x": 4,
      "y": 8,
      "z": -4,
      "name": "Rock_Slate_Cobble_Half",
      "rotation": 3
    },
    {
      "x": 4,
      "y": 0,
      "z": -3,
      "name": "Rock_Slate_Cobble"
    },
    {
      "x": 4,
      "y": 8,
      "z": -3,
      "name": "Rock_Slate_Cobble_Half",
      "rotation": 3
    },
    {
      "x": 4,
      "y": 0,
      "z": -2,
      "name": "Rock_Slate_Cobble"
    },
    {
      "x": 4,
      "y": 8,
      "z": -2,
      "name": "Rock_Slate_Cobble_Half",
      "rotation": 3
    },
    {
      "x": 4,
      "y": 0,
      "z": -1,
      "name": "Rock_Slate_Cobble"
    },
    {
      "x": 4,
      "y": 8,
      "z": -1,
      "name": "Rock_Slate_Cobble_Half",
      "rotation": 3
    },
    {
      "x": 4,
      "y": 0,
      "z": 0,
      "name": "Rock_Slate_Cobble"
    },
    {
      "x": 4,
      "y": 8,
      "z": 0,
      "name": "Rock_Slate_Cobble",
      "rotation": 1
    },
    {
      "x": 4,
      "y": 0,
      "z": 1,
      "name": "Rock_Slate_Cobble"
    },
    {
      "x": 4,
      "y": 8,
      "z": 1,
      "name": "Rock_Slate_Cobble_Half",
      "rotation": 2
    },
    {
      "x": 4,
      "y": 0,
      "z": 2,
      "name": "Rock_Slate_Cobble"
    },
    {
      "x": 4,
      "y": 8,
      "z": 2,
      "name": "Rock_Slate_Cobble_Half",
      "rotation": 2
    },
    {
      "x": 4,
      "y": 0,
      "z": 3,
      "name": "Rock_Slate_Cobble"
    },
    {
      "x": 4,
      "y": 8,
      "z": 3,
      "name": "Rock_Slate_Cobble_Half",
      "rotation": 2
    },
    {
      "x": 4,
      "y": 0,
      "z": 4,
      "name": "Rock_Slate_Cobble"
    },
    {
      "x": 4,
      "y": 8,
      "z": 4,
      "name": "Rock_Slate_Cobble_Half",
      "rotation": 2
    },
    {
      "x": 4,
      "y": 0,
      "z": 5,
      "name": "Rock_Slate_Cobble"
    },
    {
      "x": 4,
      "y": 8,
      "z": 5,
      "name": "Rock_Slate_Cobble_Half",
      "rotation": 2
    },
    {
      "x": 4,
      "y": 0,
      "z": 6,
      "name": "Rock_Slate_Cobble"
    },
    {
      "x": 4,
      "y": 8,
      "z": 6,
      "name": "Rock_Slate_Cobble_Half",
      "rotation": 2
    },
    {
      "x": 4,
      "y": 0,
      "z": 7,
      "name": "Rock_Slate_Cobble"
    },
    {
      "x": 4,
      "y": 8,
      "z": 7,
      "name": "Rock_Slate_Cobble_Half",
      "rotation": 2
    },
    {
      "x": 4,
      "y": 0,
      "z": 8,
      "name": "Rock_Slate_Cobble"
    },
    {
      "x": 4,
      "y": 8,
      "z": 8,
      "name": "Rock_Slate_Cobble_Half",
      "rotation": 2
    },
    {
      "x": 4,
      "y": 1,
      "z": 9,
      "name": "Rock_Slate_Cobble"
    },
    {
      "x": 4,
      "y": 2,
      "z": 9,
      "name": "Rock_Slate_Cobble"
    },
    {
      "x": 4,
      "y": 3,
      "z": 9,
      "name": "Rock_Slate_Cobble",
      "rotation": 2
    },
    {
      "x": 4,
      "y": 4,
      "z": 9,
      "name": "Rock_Slate_Cobble",
      "rotation": 2
    },
    {
      "x": 4,
      "y": 5,
      "z": 9,
      "name": "Rock_Slate_Cobble",
      "rotation": 2
    },
    {
      "x": 4,
      "y": 6,
      "z": 9,
      "name": "Rock_Slate_Cobble",
      "rotation": 2
    },
    {
      "x": 4,
      "y": 7,
      "z": 9,
      "name": "Rock_Slate_Cobble",
      "rotation": 2
    },
    {
      "x": 4,
      "y": 8,
      "z": 9,
      "name": "Rock_Slate_Cobble_Half",
      "rotation": 2
    },
    {
      "x": 5,
      "y": 1,
      "z": -9,
      "name": "Rock_Slate_Cobble",
      "rotation": 3
    },
    {
      "x": 5,
      "y": 2,
      "z": -9,
      "name": "Rock_Slate_Cobble",
      "rotation": 3
    },
    {
      "x": 5,
      "y": 3,
      "z": -9,
      "name": "Rock_Slate_Cobble",
      "rotation": 3
    },
    {
      "x": 5,
      "y": 4,
      "z": -9,
      "name": "Rock_Slate_Cobble",
      "rotation": 3
    },
    {
      "x": 5,
      "y": 5,
      "z": -9,
      "name": "Rock_Slate_Cobble",
      "rotation": 3
    },
    {
      "x": 5,
      "y": 6,
      "z": -9,
      "name": "Rock_Slate_Cobble",
      "rotation": 3
    },
    {
      "x": 5,
      "y": 7,
      "z": -9,
      "name": "Rock_Slate_Cobble",
      "rotation": 3
    },
    {
      "x": 5,
      "y": 8,
      "z": -9,
      "name": "Rock_Slate_Cobble_Half",
      "rotation": 3
    },
    {
      "x": 5,
      "y": 0,
      "z": -8,
      "name": "Rock_Slate_Cobble",
      "rotation": 3
    },
    {
      "x": 5,
      "y": 8,
      "z": -8,
      "name": "Rock_Slate_Cobble_Half",
      "rotation": 3
    },
    {
      "x": 5,
      "y": 0,
      "z": -7,
      "name": "Rock_Slate_Cobble",
      "rotation": 3
    },
    {
      "x": 5,
      "y": 8,
      "z": -7,
      "name": "Rock_Slate_Cobble_Half",
      "rotation": 3
    },
    {
      "x": 5,
      "y": 0,
      "z": -6,
      "name": "Rock_Slate_Cobble",
      "rotation": 3
    },
    {
      "x": 5,
      "y": 8,
      "z": -6,
      "name": "Rock_Slate_Cobble_Half",
      "rotation": 3
    },
    {
      "x": 5,
      "y": 0,
      "z": -5,
      "name": "Rock_Slate_Cobble",
      "rotation": 3
    },
    {
      "x": 5,
      "y": 8,
      "z": -5,
      "name": "Rock_Slate_Cobble_Half",
      "rotation": 3
    },
    {
      "x": 5,
      "y": 0,
      "z": -4,
      "name": "Rock_Slate_Cobble",
      "rotation": 3
    },
    {
      "x": 5,
      "y": 8,
      "z": -4,
      "name": "Rock_Slate_Cobble_Half",
      "rotation": 3
    },
    {
      "x": 5,
      "y": 0,
      "z": -3,
      "name": "Rock_Slate_Cobble"
    },
    {
      "x": 5,
      "y": 8,
      "z": -3,
      "name": "Rock_Slate_Cobble_Half",
      "rotation": 3
    },
    {
      "x": 5,
      "y": 0,
      "z": -2,
      "name": "Rock_Slate_Cobble"
    },
    {
      "x": 5,
      "y": 8,
      "z": -2,
      "name": "Rock_Slate_Cobble_Half",
      "rotation": 3
    },
    {
      "x": 5,
      "y": 0,
      "z": -1,
      "name": "Rock_Slate_Cobble"
    },
    {
      "x": 5,
      "y": 8,
      "z": -1,
      "name": "Rock_Slate_Cobble_Half",
      "rotation": 3
    },
    {
      "x": 5,
      "y": 0,
      "z": 0,
      "name": "Rock_Slate_Cobble"
    },
    {
      "x": 5,
      "y": 8,
      "z": 0,
      "name": "Rock_Slate_Cobble",
      "rotation": 1
    },
    {
      "x": 5,
      "y": 0,
      "z": 1,
      "name": "Rock_Slate_Cobble"
    },
    {
      "x": 5,
      "y": 8,
      "z": 1,
      "name": "Rock_Slate_Cobble_Half",
      "rotation": 2
    },
    {
      "x": 5,
      "y": 0,
      "z": 2,
      "name": "Rock_Slate_Cobble",
      "rotation": 2
    },
    {
      "x": 5,
      "y": 8,
      "z": 2,
      "name": "Rock_Slate_Cobble_Half",
      "rotation": 2
    },
    {
      "x": 5,
      "y": 0,
      "z": 3,
      "name": "Rock_Slate_Cobble",
      "rotation": 2
    },
    {
      "x": 5,
      "y": 8,
      "z": 3,
      "name": "Rock_Slate_Cobble_Half",
      "rotation": 2
    },
    {
      "x": 5,
      "y": 0,
      "z": 4,
      "name": "Rock_Slate_Cobble"
    },
    {
      "x": 5,
      "y": 8,
      "z": 4,
      "name": "Rock_Slate_Cobble_Half",
      "rotation": 2
    },
    {
      "x": 5,
      "y": 0,
      "z": 5,
      "name": "Rock_Slate_Cobble"
    },
    {
      "x": 5,
      "y": 8,
      "z": 5,
      "name": "Rock_Slate_Cobble_Half",
      "rotation": 2
    },
    {
      "x": 5,
      "y": 0,
      "z": 6,
      "name": "Rock_Slate_Cobble"
    },
    {
      "x": 5,
      "y": 8,
      "z": 6,
      "name": "Rock_Slate_Cobble_Half",
      "rotation": 2
    },
    {
      "x": 5,
      "y": 0,
      "z": 7,
      "name": "Rock_Slate_Cobble"
    },
    {
      "x": 5,
      "y": 8,
      "z": 7,
      "name": "Rock_Slate_Cobble_Half",
      "rotation": 2
    },
    {
      "x": 5,
      "y": 0,
      "z": 8,
      "name": "Rock_Slate_Cobble"
    },
    {
      "x": 5,
      "y": 8,
      "z": 8,
      "name": "Rock_Slate_Cobble_Half",
      "rotation": 2
    },
    {
      "x": 5,
      "y": 1,
      "z": 9,
      "name": "Rock_Slate_Cobble"
    },
    {
      "x": 5,
      "y": 2,
      "z": 9,
      "name": "Rock_Slate_Cobble"
    },
    {
      "x": 5,
      "y": 3,
      "z": 9,
      "name": "Rock_Slate_Cobble"
    },
    {
      "x": 5,
      "y": 4,
      "z": 9,
      "name": "Rock_Slate_Cobble"
    },
    {
      "x": 5,
      "y": 5,
      "z": 9,
      "name": "Rock_Slate_Cobble",
      "rotation": 2
    },
    {
      "x": 5,
      "y": 6,
      "z": 9,
      "name": "Rock_Slate_Cobble",
      "rotation": 2
    },
    {
      "x": 5,
      "y": 7,
      "z": 9,
      "name": "Rock_Slate_Cobble",
      "rotation": 2
    },
    {
      "x": 5,
      "y": 8,
      "z": 9,
      "name": "Rock_Slate_Cobble_Half",
      "rotation": 2
    },
    {
      "x": 6,
      "y": 1,
      "z": -9,
      "name": "Rock_Slate_Cobble",
      "rotation": 3
    },
    {
      "x": 6,
      "y": 2,
      "z": -9,
      "name": "Rock_Slate_Cobble",
      "rotation": 3
    },
    {
      "x": 6,
      "y": 3,
      "z": -9,
      "name": "Rock_Slate_Cobble",
      "rotation": 3
    },
    {
      "x": 6,
      "y": 4,
      "z": -9,
      "name": "Rock_Slate_Cobble",
      "rotation": 3
    },
    {
      "x": 6,
      "y": 5,
      "z": -9,
      "name": "Rock_Slate_Cobble",
      "rotation": 3
    },
    {
      "x": 6,
      "y": 6,
      "z": -9,
      "name": "Rock_Slate_Cobble",
      "rotation": 3
    },
    {
      "x": 6,
      "y": 7,
      "z": -9,
      "name": "Rock_Slate_Cobble",
      "rotation": 3
    },
    {
      "x": 6,
      "y": 8,
      "z": -9,
      "name": "Rock_Slate_Cobble_Half",
      "rotation": 3
    },
    {
      "x": 6,
      "y": 0,
      "z": -8,
      "name": "Rock_Slate_Cobble",
      "rotation": 3
    },
    {
      "x": 6,
      "y": 8,
      "z": -8,
      "name": "Rock_Slate_Cobble_Half",
      "rotation": 3
    },
    {
      "x": 6,
      "y": 0,
      "z": -7,
      "name": "Rock_Slate_Cobble",
      "rotation": 3
    },
    {
      "x": 6,
      "y": 8,
      "z": -7,
      "name": "Rock_Slate_Cobble_Half",
      "rotation": 3
    },
    {
      "x": 6,
      "y": 0,
      "z": -6,
      "name": "Rock_Slate_Cobble",
      "rotation": 3
    },
    {
      "x": 6,
      "y": 8,
      "z": -6,
      "name": "Rock_Slate_Cobble_Half",
      "rotation": 3
    },
    {
      "x": 6,
      "y": 0,
      "z": -5,
      "name": "Rock_Slate_Cobble",
      "rotation": 3
    },
    {
      "x": 6,
      "y": 8,
      "z": -5,
      "name": "Rock_Slate_Cobble_Half",
      "rotation": 3
    },
    {
      "x": 6,
      "y": 0,
      "z": -4,
      "name": "Rock_Slate_Cobble",
      "rotation": 3
    },
    {
      "x": 6,
      "y": 8,
      "z": -4,
      "name": "Rock_Slate_Cobble_Half",
      "rotation": 3
    },
    {
      "x": 6,
      "y": 0,
      "z": -3,
      "name": "Rock_Slate_Cobble",
      "rotation": 3
    },
    {
      "x": 6,
      "y": 1,
      "z": -3,
      "name": "Rock_Slate_Cobble"
    },
    {
      "x": 6,
      "y": 2,
      "z": -3,
      "name": "Rock_Slate_Cobble_Beam"
    },
    {
      "x": 6,
      "y": 3,
      "z": -3,
      "name": "Rock_Slate_Cobble_Beam"
    },
    {
      "x": 6,
      "y": 4,
      "z": -3,
      "name": "Rock_Slate_Cobble_Beam"
    },
    {
      "x": 6,
      "y": 5,
      "z": -3,
      "name": "Rock_Slate_Cobble_Beam"
    },
    {
      "x": 6,
      "y": 6,
      "z": -3,
      "name": "Rock_Slate_Cobble_Beam"
    },
    {
      "x": 6,
      "y": 7,
      "z": -3,
      "name": "Rock_Slate_Cobble_Beam",
      "rotation": 3
    },
    {
      "x": 6,
      "y": 8,
      "z": -3,
      "name": "Rock_Slate_Cobble_Half",
      "rotation": 3
    },
    {
      "x": 6,
      "y": 0,
      "z": -2,
      "name": "Rock_Slate_Cobble",
      "rotation": 3
    },
    {
      "x": 6,
      "y": 8,
      "z": -2,
      "name": "Rock_Slate_Cobble_Half",
      "rotation": 3
    },
    {
      "x": 6,
      "y": 0,
      "z": -1,
      "name": "Rock_Slate_Cobble",
      "rotation": 3
    },
    {
      "x": 6,
      "y": 8,
      "z": -1,
      "name": "Rock_Slate_Cobble_Half",
      "rotation": 3
    },
    {
      "x": 6,
      "y": 0,
      "z": 0,
      "name": "Rock_Slate_Cobble"
    },
    {
      "x": 6,
      "y": 8,
      "z": 0,
      "name": "Rock_Slate_Cobble",
      "rotation": 1
    },
    {
      "x": 6,
      "y": 0,
      "z": 1,
      "name": "Rock_Slate_Cobble"
    },
    {
      "x": 6,
      "y": 8,
      "z": 1,
      "name": "Rock_Slate_Cobble_Half",
      "rotation": 2
    },
    {
      "x": 6,
      "y": 0,
      "z": 2,
      "name": "Rock_Slate_Cobble",
      "rotation": 2
    },
    {
      "x": 6,
      "y": 8,
      "z": 2,
      "name": "Rock_Slate_Cobble_Half",
      "rotation": 2
    },
    {
      "x": 6,
      "y": 0,
      "z": 3,
      "name": "Rock_Slate_Cobble"
    },
    {
      "x": 6,
      "y": 1,
      "z": 3,
      "name": "Rock_Slate_Cobble"
    },
    {
      "x": 6,
      "y": 2,
      "z": 3,
      "name": "Rock_Slate_Cobble_Beam"
    },
    {
      "x": 6,
      "y": 3,
      "z": 3,
      "name": "Rock_Slate_Cobble_Beam",
      "rotation": 2
    },
    {
      "x": 6,
      "y": 4,
      "z": 3,
      "name": "Rock_Slate_Cobble_Beam",
      "rotation": 2
    },
    {
      "x": 6,
      "y": 5,
      "z": 3,
      "name": "Rock_Slate_Cobble_Beam",
      "rotation": 2
    },
    {
      "x": 6,
      "y": 6,
      "z": 3,
      "name": "Rock_Slate_Cobble_Beam",
      "rotation": 2
    },
    {
      "x": 6,
      "y": 7,
      "z": 3,
      "name": "Rock_Slate_Cobble_Beam",
      "rotation": 2
    },
    {
      "x": 6,
      "y": 8,
      "z": 3,
      "name": "Rock_Slate_Cobble_Half",
      "rotation": 2
    },
    {
      "x": 6,
      "y": 0,
      "z": 4,
      "name": "Rock_Slate_Cobble"
    },
    {
      "x": 6,
      "y": 8,
      "z": 4,
      "name": "Rock_Slate_Cobble_Half",
      "rotation": 2
    },
    {
      "x": 6,
      "y": 0,
      "z": 5,
      "name": "Rock_Slate_Cobble"
    },
    {
      "x": 6,
      "y": 8,
      "z": 5,
      "name": "Rock_Slate_Cobble_Half",
      "rotation": 2
    },
    {
      "x": 6,
      "y": 0,
      "z": 6,
      "name": "Rock_Slate_Cobble"
    },
    {
      "x": 6,
      "y": 8,
      "z": 6,
      "name": "Rock_Slate_Cobble_Half",
      "rotation": 2
    },
    {
      "x": 6,
      "y": 0,
      "z": 7,
      "name": "Rock_Slate_Cobble"
    },
    {
      "x": 6,
      "y": 8,
      "z": 7,
      "name": "Rock_Slate_Cobble_Half",
      "rotation": 2
    },
    {
      "x": 6,
      "y": 0,
      "z": 8,
      "name": "Rock_Slate_Cobble"
    },
    {
      "x": 6,
      "y": 8,
      "z": 8,
      "name": "Rock_Slate_Cobble_Half",
      "rotation": 2
    },
    {
      "x": 6,
      "y": 1,
      "z": 9,
      "name": "Rock_Slate_Cobble"
    },
    {
      "x": 6,
      "y": 2,
      "z": 9,
      "name": "Rock_Slate_Cobble"
    },
    {
      "x": 6,
      "y": 3,
      "z": 9,
      "name": "Rock_Slate_Cobble"
    },
    {
      "x": 6,
      "y": 4,
      "z": 9,
      "name": "Rock_Slate_Cobble"
    },
    {
      "x": 6,
      "y": 5,
      "z": 9,
      "name": "Rock_Slate_Cobble",
      "rotation": 2
    },
    {
      "x": 6,
      "y": 6,
      "z": 9,
      "name": "Rock_Slate_Cobble",
      "rotation": 2
    },
    {
      "x": 6,
      "y": 7,
      "z": 9,
      "name": "Rock_Slate_Cobble",
      "rotation": 2
    },
    {
      "x": 6,
      "y": 8,
      "z": 9,
      "name": "Rock_Slate_Cobble_Half",
      "rotation": 2
    },
    {
      "x": 7,
      "y": 1,
      "z": -9,
      "name": "Rock_Slate_Cobble",
      "rotation": 3
    },
    {
      "x": 7,
      "y": 2,
      "z": -9,
      "name": "Rock_Slate_Cobble",
      "rotation": 3
    },
    {
      "x": 7,
      "y": 3,
      "z": -9,
      "name": "Rock_Slate_Cobble",
      "rotation": 3
    },
    {
      "x": 7,
      "y": 4,
      "z": -9,
      "name": "Rock_Slate_Cobble",
      "rotation": 3
    },
    {
      "x": 7,
      "y": 5,
      "z": -9,
      "name": "Rock_Slate_Cobble",
      "rotation": 3
    },
    {
      "x": 7,
      "y": 6,
      "z": -9,
      "name": "Rock_Slate_Cobble",
      "rotation": 3
    },
    {
      "x": 7,
      "y": 7,
      "z": -9,
      "name": "Rock_Slate_Cobble",
      "rotation": 3
    },
    {
      "x": 7,
      "y": 8,
      "z": -9,
      "name": "Rock_Slate_Cobble_Half",
      "rotation": 3
    },
    {
      "x": 7,
      "y": 0,
      "z": -8,
      "name": "Rock_Slate_Cobble",
      "rotation": 3
    },
    {
      "x": 7,
      "y": 8,
      "z": -8,
      "name": "Rock_Slate_Cobble",
      "rotation": 3
    },
    {
      "x": 7,
      "y": 0,
      "z": -7,
      "name": "Rock_Slate_Cobble",
      "rotation": 3
    },
    {
      "x": 7,
      "y": 8,
      "z": -7,
      "name": "Rock_Slate_Cobble_Half",
      "rotation": 3
    },
    {
      "x": 7,
      "y": 0,
      "z": -6,
      "name": "Rock_Slate_Cobble",
      "rotation": 3
    },
    {
      "x": 7,
      "y": 8,
      "z": -6,
      "name": "Rock_Slate_Cobble_Half",
      "rotation": 3
    },
    {
      "x": 7,
      "y": 0,
      "z": -5,
      "name": "Rock_Slate_Cobble",
      "rotation": 3
    },
    {
      "x": 7,
      "y": 8,
      "z": -5,
      "name": "Rock_Slate_Cobble_Half",
      "rotation": 3
    },
    {
      "x": 7,
      "y": 0,
      "z": -4,
      "name": "Rock_Slate_Cobble",
      "rotation": 3
    },
    {
      "x": 7,
      "y": 8,
      "z": -4,
      "name": "Rock_Slate_Cobble_Half",
      "rotation": 3
    },
    {
      "x": 7,
      "y": 0,
      "z": -3,
      "name": "Rock_Slate_Cobble",
      "rotation": 3
    },
    {
      "x": 7,
      "y": 8,
      "z": -3,
      "name": "Rock_Slate_Cobble_Half",
      "rotation": 3
    },
    {
      "x": 7,
      "y": 0,
      "z": -2,
      "name": "Rock_Slate_Cobble",
      "rotation": 3
    },
    {
      "x": 7,
      "y": 8,
      "z": -2,
      "name": "Rock_Slate_Cobble_Half",
      "rotation": 3
    },
    {
      "x": 7,
      "y": 0,
      "z": -1,
      "name": "Rock_Slate_Cobble",
      "rotation": 3
    },
    {
      "x": 7,
      "y": 8,
      "z": -1,
      "name": "Rock_Slate_Cobble_Half",
      "rotation": 3
    },
    {
      "x": 7,
      "y": 0,
      "z": 0,
      "name": "Rock_Slate_Cobble"
    },
    {
      "x": 7,
      "y": 8,
      "z": 0,
      "name": "Rock_Slate_Cobble",
      "rotation": 1
    },
    {
      "x": 7,
      "y": 0,
      "z": 1,
      "name": "Rock_Slate_Cobble",
      "rotation": 2
    },
    {
      "x": 7,
      "y": 8,
      "z": 1,
      "name": "Rock_Slate_Cobble_Half",
      "rotation": 2
    },
    {
      "x": 7,
      "y": 0,
      "z": 2,
      "name": "Rock_Slate_Cobble",
      "rotation": 2
    },
    {
      "x": 7,
      "y": 8,
      "z": 2,
      "name": "Rock_Slate_Cobble_Half",
      "rotation": 2
    },
    {
      "x": 7,
      "y": 0,
      "z": 3,
      "name": "Rock_Slate_Cobble"
    },
    {
      "x": 7,
      "y": 8,
      "z": 3,
      "name": "Rock_Slate_Cobble_Half",
      "rotation": 2
    },
    {
      "x": 7,
      "y": 0,
      "z": 4,
      "name": "Rock_Slate_Cobble"
    },
    {
      "x": 7,
      "y": 8,
      "z": 4,
      "name": "Rock_Slate_Cobble_Half",
      "rotation": 2
    },
    {
      "x": 7,
      "y": 0,
      "z": 5,
      "name": "Rock_Slate_Cobble"
    },
    {
      "x": 7,
      "y": 8,
      "z": 5,
      "name": "Rock_Slate_Cobble_Half",
      "rotation": 2
    },
    {
      "x": 7,
      "y": 0,
      "z": 6,
      "name": "Rock_Slate_Cobble"
    },
    {
      "x": 7,
      "y": 8,
      "z": 6,
      "name": "Rock_Slate_Cobble_Half",
      "rotation": 2
    },
    {
      "x": 7,
      "y": 0,
      "z": 7,
      "name": "Rock_Slate_Cobble"
    },
    {
      "x": 7,
      "y": 8,
      "z": 7,
      "name": "Rock_Slate_Cobble_Half",
      "rotation": 2
    },
    {
      "x": 7,
      "y": 0,
      "z": 8,
      "name": "Rock_Slate_Cobble"
    },
    {
      "x": 7,
      "y": 8,
      "z": 8,
      "name": "Rock_Slate_Cobble",
      "rotation": 2
    },
    {
      "x": 7,
      "y": 1,
      "z": 9,
      "name": "Rock_Slate_Cobble"
    },
    {
      "x": 7,
      "y": 2,
      "z": 9,
      "name": "Rock_Slate_Cobble"
    },
    {
      "x": 7,
      "y": 3,
      "z": 9,
      "name": "Rock_Slate_Cobble"
    },
    {
      "x": 7,
      "y": 4,
      "z": 9,
      "name": "Rock_Slate_Cobble"
    },
    {
      "x": 7,
      "y": 5,
      "z": 9,
      "name": "Rock_Slate_Cobble"
    },
    {
      "x": 7,
      "y": 6,
      "z": 9,
      "name": "Rock_Slate_Cobble",
      "rotation": 2
    },
    {
      "x": 7,
      "y": 7,
      "z": 9,
      "name": "Rock_Slate_Cobble",
      "rotation": 2
    },
    {
      "x": 8,
      "y": 1,
      "z": -9,
      "name": "Rock_Slate_Cobble",
      "rotation": 3
    },
    {
      "x": 8,
      "y": 2,
      "z": -9,
      "name": "Rock_Slate_Cobble",
      "rotation": 3
    },
    {
      "x": 8,
      "y": 3,
      "z": -9,
      "name": "Rock_Slate_Cobble",
      "rotation": 3
    },
    {
      "x": 8,
      "y": 4,
      "z": -9,
      "name": "Rock_Slate_Cobble",
      "rotation": 3
    },
    {
      "x": 8,
      "y": 5,
      "z": -9,
      "name": "Rock_Slate_Cobble",
      "rotation": 3
    },
    {
      "x": 8,
      "y": 6,
      "z": -9,
      "name": "Rock_Slate_Cobble",
      "rotation": 3
    },
    {
      "x": 8,
